Workbook

Sheet Regression
A1: P/Q LOG-LOG REGRESSION | D = P × [acid]^Q | 7 experimental points × 26 elements × 2 acid systems (H₂SO₄ loading / HNO₃ stripping)
A2: INPUT | E2: CALC | I2: OUTPUT
A4: LOADING DATA (H₂SO₄ system) | BE4: STRIPPING DATA (HNO₃ system)
A5: Pt# | B5: H₂SO₄ (N) | C5: C_aq Al (ppm) | D5: C_aq Sc (ppm) | E5: C_aq Fe (ppm) | F5: C_aq Co (ppm) | G5: C_aq Zn (ppm) | H5: C_aq Ga (ppm) | I5: C_aq Rb (ppm) | J5: C_aq Y (ppm) | K5: C_aq Zr (ppm) | L5: C_aq La (ppm) | M5: C_aq Ce (ppm) | N5: C_aq Pr (ppm) | O5: C_aq Nd (ppm) | P5: C_aq Sm (ppm) | Q5: C_aq Eu (ppm) | R5: C_aq Gd (ppm) | S5: C_aq Tb (ppm) | T5: C_aq Dy (ppm) | U5: C_aq Ho (ppm) | V5: C_aq Er (ppm) | W5: C_aq Tm (ppm) | X5: C_aq Yb (ppm) | Y5: C_aq Lu (ppm) | Z5: C_aq Hf (ppm) | AA5: C_aq Th (ppm) | AB5: C_aq U (ppm) | AC5: C_org Al (ppm) | AD5: C_org Sc (ppm) | AE5: C_org Fe (ppm) | AF5: C_org Co (ppm) | AG5: C_org Zn (ppm) | AH5: C_org Ga (ppm) | AI5: C_org Rb (ppm) | AJ5: C_org Y (ppm) | AK5: C_org Zr (ppm) | AL5: C_org La (ppm) | AM5: C_org Ce (ppm) | AN5: C_org Pr (ppm) | AO5: C_org Nd (ppm) | AP5: C_org Sm (ppm) | AQ5: C_org Eu (ppm) | AR5: C_org Gd (ppm) | AS5: C_org Tb (ppm) | AT5: C_org Dy (ppm) | AU5: C_org Ho (ppm) | AV5: C_org Er (ppm) | AW5: C_org Tm (ppm) | AX5: C_org Yb (ppm) | AY5: C_org Lu (ppm) | AZ5: C_org Hf (ppm) | BA5: C_org Th (ppm) | BB5: C_org U (ppm) | BE5: Pt# | BF5: HNO₃ (N) | BG5: C_aq Al (ppm) | BH5: C_aq Sc (ppm) | BI5: C_aq Fe (ppm) | BJ5: C_aq Co (ppm) | BK5: C_aq Zn (ppm) | BL5: C_aq Ga (ppm) | BM5: C_aq Rb (ppm) | BN5: C_aq Y (ppm) | BO5: C_aq Zr (ppm) | BP5: C_aq La (ppm) | BQ5: C_aq Ce (ppm) | BR5: C_aq Pr (ppm) | BS5: C_aq Nd (ppm) | BT5: C_aq Sm (ppm) | BU5: C_aq Eu (ppm) | BV5: C_aq Gd (ppm) | BW5: C_aq Tb (ppm) | BX5: C_aq Dy (ppm) | BY5: C_aq Ho (ppm) | BZ5: C_aq Er (ppm) | CA5: C_aq Tm (ppm) | CB5: C_aq Yb (ppm) | CC5: C_aq Lu (ppm) | CD5: C_aq Hf (ppm) | CE5: C_aq Th (ppm) | CF5: C_aq U (ppm) | CG5: C_org Al (ppm) | CH5: C_org Sc (ppm) | CI5: C_org Fe (ppm) | CJ5: C_org Co (ppm) | CK5: C_org Zn (ppm) | CL5: C_org Ga (ppm) | CM5: C_org Rb (ppm) | CN5: C_org Y (ppm) | CO5: C_org Zr (ppm) | CP5: C_org La (ppm) | CQ5: C_org Ce (ppm) | CR5: C_org Pr (ppm) | CS5: C_org Nd (ppm) | CT5: C_org Sm (ppm) | CU5: C_org Eu (ppm) | CV5: C_org Gd (ppm) | CW5: C_org Tb (ppm) | CX5: C_org Dy (ppm) | CY5: C_org Ho (ppm) | CZ5: C_org Er (ppm) | DA5: C_org Tm (ppm) | DB5: C_org Yb (ppm) | DC5: C_org Lu (ppm) | DD5: C_org Hf (ppm) | DE5: C_org Th (ppm) | DF5: C_org U (ppm)
A6: 1 | BE6: 1
A7: 2 | BE7: 2
A8: 3 | BE8: 3
A9: 4 | BE9: 4
A10: 5 | BE10: 5
A11: 6 | BE11: 6
A12: 7 | BE12: 7
A14: D VALUES (C_org / C_aq) — Loading | BE14: D VALUES (C_org / C_aq) — Stripping
A15: Pt# | B15: D_Al | C15: D_Sc | D15: D_Fe | E15: D_Co | F15: D_Zn | G15: D_Ga | H15: D_Rb | I15: D_Y | J15: D_Zr | K15: D_La | L15: D_Ce | M15: D_Pr | N15: D_Nd | O15: D_Sm | P15: D_Eu | Q15: D_Gd | R15: D_Tb | S15: D_Dy | T15: D_Ho | U15: D_Er | V15: D_Tm | W15: D_Yb | X15: D_Lu | Y15: D_Hf | Z15: D_Th | AA15: D_U | BE15: Pt# | BF15: D_Al | BG15: D_Sc | BH15: D_Fe | BI15: D_Co | BJ15: D_Zn | BK15: D_Ga | BL15: D_Rb | BM15: D_Y | BN15: D_Zr | BO15: D_La | BP15: D_Ce | BQ15: D_Pr | BR15: D_Nd | BS15: D_Sm | BT15: D_Eu | BU15: D_Gd | BV15: D_Tb | BW15: D_Dy | BX15: D_Ho | BY15: D_Er | BZ15: D_Tm | CA15: D_Yb | CB15: D_Lu | CC15: D_Hf | CD15: D_Th | CE15: D_U
A16: 1 | B16: =IFERROR(IF(OR(C6="",AC6="",VALUE(C6)=0),"",AC6/C6),"N/A") | C16: =IFERROR(IF(OR(D6="",AD6="",VALUE(D6)=0),"",AD6/D6),"N/A") | D16: =IFERROR(IF(OR(E6="",AE6="",VALUE(E6)=0),"",AE6/E6),"N/A") | E16: =IFERROR(IF(OR(F6="",AF6="",VALUE(F6)=0),"",AF6/F6),"N/A") | F16: =IFERROR(IF(OR(G6="",AG6="",VALUE(G6)=0),"",AG6/G6),"N/A") | G16: =IFERROR(IF(OR(H6="",AH6="",VALUE(H6)=0),"",AH6/H6),"N/A") | H16: =IFERROR(IF(OR(I6="",AI6="",VALUE(I6)=0),"",AI6/I6),"N/A") | I16: =IFERROR(IF(OR(J6="",AJ6="",VALUE(J6)=0),"",AJ6/J6),"N/A") | ... AA16: =IFERROR(IF(OR(AB6="",BB6="",VALUE(AB6)=0),"",BB6/AB6),"N/A") | BE16: 1 | BF16: =IFERROR(IF(OR(BG6="",CG6="",VALUE(BG6)=0),"",CG6/BG6),"N/A") | BG16: =IFERROR(IF(OR(BH6="",CH6="",VALUE(BH6)=0),"",CH6/BH6),"N/A") | BH16: =IFERROR(IF(OR(BI6="",CI6="",VALUE(BI6)=0),"",CI6/BI6),"N/A") | BI16: =IFERROR(IF(OR(BJ6="",CJ6="",VALUE(BJ6)=0),"",CJ6/BJ6),"N/A") | BJ16: =IFERROR(IF(OR(BK6="",CK6="",VALUE(BK6)=0),"",CK6/BK6),"N/A") | BK16: =IFERROR(IF(OR(BL6="",CL6="",VALUE(BL6)=0),"",CL6/BL6),"N/A") | BL16: =IFERROR(IF(OR(BM6="",CM6="",VALUE(BM6)=0),"",CM6/BM6),"N/A") | BM16: =IFERROR(IF(OR(BN6="",CN6="",VALUE(BN6)=0),"",CN6/BN6),"N/A") | ... CE16: =IFERROR(IF(OR(CF6="",DF6="",VALUE(CF6)=0),"",DF6/CF6),"N/A")
A17: 2 | B17: =IFERROR(IF(OR(C7="",AC7="",VALUE(C7)=0),"",AC7/C7),"N/A") | C17: =IFERROR(IF(OR(D7="",AD7="",VALUE(D7)=0),"",AD7/D7),"N/A") | D17: =IFERROR(IF(OR(E7="",AE7="",VALUE(E7)=0),"",AE7/E7),"N/A") | E17: =IFERROR(IF(OR(F7="",AF7="",VALUE(F7)=0),"",AF7/F7),"N/A") | F17: =IFERROR(IF(OR(G7="",AG7="",VALUE(G7)=0),"",AG7/G7),"N/A") | G17: =IFERROR(IF(OR(H7="",AH7="",VALUE(H7)=0),"",AH7/H7),"N/A") | H17: =IFERROR(IF(OR(I7="",AI7="",VALUE(I7)=0),"",AI7/I7),"N/A") | I17: =IFERROR(IF(OR(J7="",AJ7="",VALUE(J7)=0),"",AJ7/J7),"N/A") | ... AA17: =IFERROR(IF(OR(AB7="",BB7="",VALUE(AB7)=0),"",BB7/AB7),"N/A") | BE17: 2 | BF17: =IFERROR(IF(OR(BG7="",CG7="",VALUE(BG7)=0),"",CG7/BG7),"N/A") | BG17: =IFERROR(IF(OR(BH7="",CH7="",VALUE(BH7)=0),"",CH7/BH7),"N/A") | BH17: =IFERROR(IF(OR(BI7="",CI7="",VALUE(BI7)=0),"",CI7/BI7),"N/A") | BI17: =IFERROR(IF(OR(BJ7="",CJ7="",VALUE(BJ7)=0),"",CJ7/BJ7),"N/A") | BJ17: =IFERROR(IF(OR(BK7="",CK7="",VALUE(BK7)=0),"",CK7/BK7),"N/A") | BK17: =IFERROR(IF(OR(BL7="",CL7="",VALUE(BL7)=0),"",CL7/BL7),"N/A") | BL17: =IFERROR(IF(OR(BM7="",CM7="",VALUE(BM7)=0),"",CM7/BM7),"N/A") | BM17: =IFERROR(IF(OR(BN7="",CN7="",VALUE(BN7)=0),"",CN7/BN7),"N/A") | ... CE17: =IFERROR(IF(OR(CF7="",DF7="",VALUE(CF7)=0),"",DF7/CF7),"N/A")
A18: 3 | B18: =IFERROR(IF(OR(C8="",AC8="",VALUE(C8)=0),"",AC8/C8),"N/A") | C18: =IFERROR(IF(OR(D8="",AD8="",VALUE(D8)=0),"",AD8/D8),"N/A") | D18: =IFERROR(IF(OR(E8="",AE8="",VALUE(E8)=0),"",AE8/E8),"N/A") | E18: =IFERROR(IF(OR(F8="",AF8="",VALUE(F8)=0),"",AF8/F8),"N/A") | F18: =IFERROR(IF(OR(G8="",AG8="",VALUE(G8)=0),"",AG8/G8),"N/A") | G18: =IFERROR(IF(OR(H8="",AH8="",VALUE(H8)=0),"",AH8/H8),"N/A") | H18: =IFERROR(IF(OR(I8="",AI8="",VALUE(I8)=0),"",AI8/I8),"N/A") | I18: =IFERROR(IF(OR(J8="",AJ8="",VALUE(J8)=0),"",AJ8/J8),"N/A") | ... AA18: =IFERROR(IF(OR(AB8="",BB8="",VALUE(AB8)=0),"",BB8/AB8),"N/A") | BE18: 3 | BF18: =IFERROR(IF(OR(BG8="",CG8="",VALUE(BG8)=0),"",CG8/BG8),"N/A") | BG18: =IFERROR(IF(OR(BH8="",CH8="",VALUE(BH8)=0),"",CH8/BH8),"N/A") | BH18: =IFERROR(IF(OR(BI8="",CI8="",VALUE(BI8)=0),"",CI8/BI8),"N/A") | BI18: =IFERROR(IF(OR(BJ8="",CJ8="",VALUE(BJ8)=0),"",CJ8/BJ8),"N/A") | BJ18: =IFERROR(IF(OR(BK8="",CK8="",VALUE(BK8)=0),"",CK8/BK8),"N/A") | BK18: =IFERROR(IF(OR(BL8="",CL8="",VALUE(BL8)=0),"",CL8/BL8),"N/A") | BL18: =IFERROR(IF(OR(BM8="",CM8="",VALUE(BM8)=0),"",CM8/BM8),"N/A") | BM18: =IFERROR(IF(OR(BN8="",CN8="",VALUE(BN8)=0),"",CN8/BN8),"N/A") | ... CE18: =IFERROR(IF(OR(CF8="",DF8="",VALUE(CF8)=0),"",DF8/CF8),"N/A")
A19: 4 | B19: =IFERROR(IF(OR(C9="",AC9="",VALUE(C9)=0),"",AC9/C9),"N/A") | C19: =IFERROR(IF(OR(D9="",AD9="",VALUE(D9)=0),"",AD9/D9),"N/A") | D19: =IFERROR(IF(OR(E9="",AE9="",VALUE(E9)=0),"",AE9/E9),"N/A") | E19: =IFERROR(IF(OR(F9="",AF9="",VALUE(F9)=0),"",AF9/F9),"N/A") | F19: =IFERROR(IF(OR(G9="",AG9="",VALUE(G9)=0),"",AG9/G9),"N/A") | G19: =IFERROR(IF(OR(H9="",AH9="",VALUE(H9)=0),"",AH9/H9),"N/A") | H19: =IFERROR(IF(OR(I9="",AI9="",VALUE(I9)=0),"",AI9/I9),"N/A") | I19: =IFERROR(IF(OR(J9="",AJ9="",VALUE(J9)=0),"",AJ9/J9),"N/A") | ... AA19: =IFERROR(IF(OR(AB9="",BB9="",VALUE(AB9)=0),"",BB9/AB9),"N/A") | BE19: 4 | BF19: =IFERROR(IF(OR(BG9="",CG9="",VALUE(BG9)=0),"",CG9/BG9),"N/A") | BG19: =IFERROR(IF(OR(BH9="",CH9="",VALUE(BH9)=0),"",CH9/BH9),"N/A") | BH19: =IFERROR(IF(OR(BI9="",CI9="",VALUE(BI9)=0),"",CI9/BI9),"N/A") | BI19: =IFERROR(IF(OR(BJ9="",CJ9="",VALUE(BJ9)=0),"",CJ9/BJ9),"N/A") | BJ19: =IFERROR(IF(OR(BK9="",CK9="",VALUE(BK9)=0),"",CK9/BK9),"N/A") | BK19: =IFERROR(IF(OR(BL9="",CL9="",VALUE(BL9)=0),"",CL9/BL9),"N/A") | BL19: =IFERROR(IF(OR(BM9="",CM9="",VALUE(BM9)=0),"",CM9/BM9),"N/A") | BM19: =IFERROR(IF(OR(BN9="",CN9="",VALUE(BN9)=0),"",CN9/BN9),"N/A") | ... CE19: =IFERROR(IF(OR(CF9="",DF9="",VALUE(CF9)=0),"",DF9/CF9),"N/A")
A20: 5 | B20: =IFERROR(IF(OR(C10="",AC10="",VALUE(C10)=0),"",AC10/C10),"N/A") | C20: =IFERROR(IF(OR(D10="",AD10="",VALUE(D10)=0),"",AD10/D10),"N/A") | D20: =IFERROR(IF(OR(E10="",AE10="",VALUE(E10)=0),"",AE10/E10),"N/A") | E20: =IFERROR(IF(OR(F10="",AF10="",VALUE(F10)=0),"",AF10/F10),"N/A") | F20: =IFERROR(IF(OR(G10="",AG10="",VALUE(G10)=0),"",AG10/G10),"N/A") | G20: =IFERROR(IF(OR(H10="",AH10="",VALUE(H10)=0),"",AH10/H10),"N/A") | H20: =IFERROR(IF(OR(I10="",AI10="",VALUE(I10)=0),"",AI10/I10),"N/A") | I20: =IFERROR(IF(OR(J10="",AJ10="",VALUE(J10)=0),"",AJ10/J10),"N/A") | ... AA20: =IFERROR(IF(OR(AB10="",BB10="",VALUE(AB10)=0),"",BB10/AB10),"N/A") | BE20: 5 | BF20: =IFERROR(IF(OR(BG10="",CG10="",VALUE(BG10)=0),"",CG10/BG10),"N/A") | BG20: =IFERROR(IF(OR(BH10="",CH10="",VALUE(BH10)=0),"",CH10/BH10),"N/A") | BH20: =IFERROR(IF(OR(BI10="",CI10="",VALUE(BI10)=0),"",CI10/BI10),"N/A") | BI20: =IFERROR(IF(OR(BJ10="",CJ10="",VALUE(BJ10)=0),"",CJ10/BJ10),"N/A") | BJ20: =IFERROR(IF(OR(BK10="",CK10="",VALUE(BK10)=0),"",CK10/BK10),"N/A") | BK20: =IFERROR(IF(OR(BL10="",CL10="",VALUE(BL10)=0),"",CL10/BL10),"N/A") | BL20: =IFERROR(IF(OR(BM10="",CM10="",VALUE(BM10)=0),"",CM10/BM10),"N/A") | BM20: =IFERROR(IF(OR(BN10="",CN10="",VALUE(BN10)=0),"",CN10/BN10),"N/A") | ... CE20: =IFERROR(IF(OR(CF10="",DF10="",VALUE(CF10)=0),"",DF10/CF10),"N/A")
A21: 6 | B21: =IFERROR(IF(OR(C11="",AC11="",VALUE(C11)=0),"",AC11/C11),"N/A") | C21: =IFERROR(IF(OR(D11="",AD11="",VALUE(D11)=0),"",AD11/D11),"N/A") | D21: =IFERROR(IF(OR(E11="",AE11="",VALUE(E11)=0),"",AE11/E11),"N/A") | E21: =IFERROR(IF(OR(F11="",AF11="",VALUE(F11)=0),"",AF11/F11),"N/A") | F21: =IFERROR(IF(OR(G11="",AG11="",VALUE(G11)=0),"",AG11/G11),"N/A") | G21: =IFERROR(IF(OR(H11="",AH11="",VALUE(H11)=0),"",AH11/H11),"N/A") | H21: =IFERROR(IF(OR(I11="",AI11="",VALUE(I11)=0),"",AI11/I11),"N/A") | I21: =IFERROR(IF(OR(J11="",AJ11="",VALUE(J11)=0),"",AJ11/J11),"N/A") | ... AA21: =IFERROR(IF(OR(AB11="",BB11="",VALUE(AB11)=0),"",BB11/AB11),"N/A") | BE21: 6 | BF21: =IFERROR(IF(OR(BG11="",CG11="",VALUE(BG11)=0),"",CG11/BG11),"N/A") | BG21: =IFERROR(IF(OR(BH11="",CH11="",VALUE(BH11)=0),"",CH11/BH11),"N/A") | BH21: =IFERROR(IF(OR(BI11="",CI11="",VALUE(BI11)=0),"",CI11/BI11),"N/A") | BI21: =IFERROR(IF(OR(BJ11="",CJ11="",VALUE(BJ11)=0),"",CJ11/BJ11),"N/A") | BJ21: =IFERROR(IF(OR(BK11="",CK11="",VALUE(BK11)=0),"",CK11/BK11),"N/A") | BK21: =IFERROR(IF(OR(BL11="",CL11="",VALUE(BL11)=0),"",CL11/BL11),"N/A") | BL21: =IFERROR(IF(OR(BM11="",CM11="",VALUE(BM11)=0),"",CM11/BM11),"N/A") | BM21: =IFERROR(IF(OR(BN11="",CN11="",VALUE(BN11)=0),"",CN11/BN11),"N/A") | ... CE21: =IFERROR(IF(OR(CF11="",DF11="",VALUE(CF11)=0),"",DF11/CF11),"N/A")
A22: 7 | B22: =IFERROR(IF(OR(C12="",AC12="",VALUE(C12)=0),"",AC12/C12),"N/A") | C22: =IFERROR(IF(OR(D12="",AD12="",VALUE(D12)=0),"",AD12/D12),"N/A") | D22: =IFERROR(IF(OR(E12="",AE12="",VALUE(E12)=0),"",AE12/E12),"N/A") | E22: =IFERROR(IF(OR(F12="",AF12="",VALUE(F12)=0),"",AF12/F12),"N/A") | F22: =IFERROR(IF(OR(G12="",AG12="",VALUE(G12)=0),"",AG12/G12),"N/A") | G22: =IFERROR(IF(OR(H12="",AH12="",VALUE(H12)=0),"",AH12/H12),"N/A") | H22: =IFERROR(IF(OR(I12="",AI12="",VALUE(I12)=0),"",AI12/I12),"N/A") | I22: =IFERROR(IF(OR(J12="",AJ12="",VALUE(J12)=0),"",AJ12/J12),"N/A") | ... AA22: =IFERROR(IF(OR(AB12="",BB12="",VALUE(AB12)=0),"",BB12/AB12),"N/A") | BE22: 7 | BF22: =IFERROR(IF(OR(BG12="",CG12="",VALUE(BG12)=0),"",CG12/BG12),"N/A") | BG22: =IFERROR(IF(OR(BH12="",CH12="",VALUE(BH12)=0),"",CH12/BH12),"N/A") | BH22: =IFERROR(IF(OR(BI12="",CI12="",VALUE(BI12)=0),"",CI12/BI12),"N/A") | BI22: =IFERROR(IF(OR(BJ12="",CJ12="",VALUE(BJ12)=0),"",CJ12/BJ12),"N/A") | BJ22: =IFERROR(IF(OR(BK12="",CK12="",VALUE(BK12)=0),"",CK12/BK12),"N/A") | BK22: =IFERROR(IF(OR(BL12="",CL12="",VALUE(BL12)=0),"",CL12/BL12),"N/A") | BL22: =IFERROR(IF(OR(BM12="",CM12="",VALUE(BM12)=0),"",CM12/BM12),"N/A") | BM22: =IFERROR(IF(OR(BN12="",CN12="",VALUE(BN12)=0),"",CN12/BN12),"N/A") | ... CE22: =IFERROR(IF(OR(CF12="",DF12="",VALUE(CF12)=0),"",DF12/CF12),"N/A")
A24: REGRESSION SUMMARY (n=7 points per element per acid system)
A25: Element | B25: n_valid | C25: P_load | D25: Q_load | E25: R²_load | F25: R²adj_load | G25: SE_Q_load | H25: P_strip | I25: Q_strip | J25: R²_strip | K25: R²adj_strip | L25: SE_Q_strip | M25: Notes
A26: Al | B26: =SUMPRODUCT((ISNUMBER(B16:B22)*1)) | C26: =IFERROR(IF(SUMPRODUCT(ISNUMBER(B16:B22)*1)<2,"Need≥2",EXP(INTERCEPT(IF(ISNUMBER(B16:B22),LN(B16:B22),FALSE),IF(ISNUMBER(B16:B22),LN(B6:B12),FALSE)))),"N/A") | D26: =IFERROR(IF(SUMPRODUCT(ISNUMBER(B16:B22)*1)<2,"Need≥2",SLOPE(IF(ISNUMBER(B16:B22),LN(B16:B22),FALSE),IF(ISNUMBER(B16:B22),LN(B6:B12),FALSE))),"N/A") | E26: =IFERROR(IF(SUMPRODUCT(ISNUMBER(B16:B22)*1)<2,"Need≥2",RSQ(IF(ISNUMBER(B16:B22),LN(B16:B22),FALSE),IF(ISNUMBER(B16:B22),LN(B6:B12),FALSE))),"N/A") | F26: =IFERROR(IF(SUMPRODUCT(ISNUMBER(B16:B22)*1)<3,"Need≥3",1-(1-(IFERROR(IF(SUMPRODUCT(ISNUMBER(B16:B22)*1)<2,"Need≥2",RSQ(IF(ISNUMBER(B16:B22),LN(B16:B22),FALSE),IF(ISNUMBER(B16:B22),LN(B6:B12),FALSE))),"N/A")))*(B26-1)/(B26-2)),"N/A") | G26: =IFERROR(IF(SUMPRODUCT(ISNUMBER(B16:B22)*1)<3,"Need≥3",SQRT((1-(IFERROR(IF(SUMPRODUCT(ISNUMBER(B16:B22)*1)<2,"Need≥2",RSQ(IF(ISNUMBER(B16:B22),LN(B16:B22),FALSE),IF(ISNUMBER(B16:B22),LN(B6:B12),FALSE))),"N/A")))*VAR(IF(ISNUMBER(B16:B22),LN(B16:B22),FALSE))/((B26-2)*VAR(IF(ISNUMBER(B16:B22),LN(B6:B12),FALSE))))),"N/A") | H26: =IFERROR(IF(SUMPRODUCT(ISNUMBER(BF16:BF22)*1)<2,"Need≥2",EXP(INTERCEPT(IF(ISNUMBER(BF16:BF22),LN(BF16:BF22),FALSE),IF(ISNUMBER(BF16:BF22),LN(BF6:BF12),FALSE)))),"N/A") | I26: =IFERROR(IF(SUMPRODUCT(ISNUMBER(BF16:BF22)*1)<2,"Need≥2",SLOPE(IF(ISNUMBER(BF16:BF22),LN(BF16:BF22),FALSE),IF(ISNUMBER(BF16:BF22),LN(BF6:BF12),FALSE))),"N/A") | J26: =IFERROR(IF(SUMPRODUCT(ISNUMBER(BF16:BF22)*1)<2,"Need≥2",RSQ(IF(ISNUMBER(BF16:BF22),LN(BF16:BF22),FALSE),IF(ISNUMBER(BF16:BF22),LN(BF6:BF12),FALSE))),"N/A") | K26: =IFERROR(IF(SUMPRODUCT(ISNUMBER(BF16:BF22)*1)<3,"Need≥3",1-(1-(IFERROR(IF(SUMPRODUCT(ISNUMBER(BF16:BF22)*1)<2,"Need≥2",RSQ(IF(ISNUMBER(BF16:BF22),LN(BF16:BF22),FALSE),IF(ISNUMBER(BF16:BF22),LN(BF6:BF12),FALSE))),"N/A")))*(B26-1)/(B26-2)),"N/A") | L26: =IFERROR(IF(SUMPRODUCT(ISNUMBER(BF16:BF22)*1)<3,"Need≥3",SQRT((1-(IFERROR(IF(SUMPRODUCT(ISNUMBER(BF16:BF22)*1)<2,"Need≥2",RSQ(IF(ISNUMBER(BF16:BF22),LN(BF16:BF22),FALSE),IF(ISNUMBER(BF16:BF22),LN(BF6:BF12),FALSE))),"N/A")))*VAR(IF(ISNUMBER(BF16:BF22),LN(BF16:BF22),FALSE))/((B26-2)*VAR(IF(ISNUMBER(BF16:BF22),LN(BF6:BF12),FALSE))))),"N/A") | M26: =IF(ISNUMBER(F26),IF(F26<0.85,"⚠ Check fit","OK"),"")
A27: Sc | B27: =SUMPRODUCT((ISNUMBER(C16:C22)*1)) | C27: =IFERROR(IF(SUMPRODUCT(ISNUMBER(C16:C22)*1)<2,"Need≥2",EXP(INTERCEPT(IF(ISNUMBER(C16:C22),LN(C16:C22),FALSE),IF(ISNUMBER(C16:C22),LN(B6:B12),FALSE)))),"N/A") | D27: =IFERROR(IF(SUMPRODUCT(ISNUMBER(C16:C22)*1)<2,"Need≥2",SLOPE(IF(ISNUMBER(C16:C22),LN(C16:C22),FALSE),IF(ISNUMBER(C16:C22),LN(B6:B12),FALSE))),"N/A") | E27: =IFERROR(IF(SUMPRODUCT(ISNUMBER(C16:C22)*1)<2,"Need≥2",RSQ(IF(ISNUMBER(C16:C22),LN(C16:C22),FALSE),IF(ISNUMBER(C16:C22),LN(B6:B12),FALSE))),"N/A") | F27: =IFERROR(IF(SUMPRODUCT(ISNUMBER(C16:C22)*1)<3,"Need≥3",1-(1-(IFERROR(IF(SUMPRODUCT(ISNUMBER(C16:C22)*1)<2,"Need≥2",RSQ(IF(ISNUMBER(C16:C22),LN(C16:C22),FALSE),IF(ISNUMBER(C16:C22),LN(B6:B12),FALSE))),"N/A")))*(B27-1)/(B27-2)),"N/A") | G27: =IFERROR(IF(SUMPRODUCT(ISNUMBER(C16:C22)*1)<3,"Need≥3",SQRT((1-(IFERROR(IF(SUMPRODUCT(ISNUMBER(C16:C22)*1)<2,"Need≥2",RSQ(IF(ISNUMBER(C16:C22),LN(C16:C22),FALSE),IF(ISNUMBER(C16:C22),LN(B6:B12),FALSE))),"N/A")))*VAR(IF(ISNUMBER(C16:C22),LN(C16:C22),FALSE))/((B27-2)*VAR(IF(ISNUMBER(C16:C22),LN(B6:B12),FALSE))))),"N/A") | H27: =IFERROR(IF(SUMPRODUCT(ISNUMBER(BG16:BG22)*1)<2,"Need≥2",EXP(INTERCEPT(IF(ISNUMBER(BG16:BG22),LN(BG16:BG22),FALSE),IF(ISNUMBER(BG16:BG22),LN(BF6:BF12),FALSE)))),"N/A") | I27: =IFERROR(IF(SUMPRODUCT(ISNUMBER(BG16:BG22)*1)<2,"Need≥2",SLOPE(IF(ISNUMBER(BG16:BG22),LN(BG16:BG22),FALSE),IF(ISNUMBER(BG16:BG22),LN(BF6:BF12),FALSE))),"N/A") | J27: =IFERROR(IF(SUMPRODUCT(ISNUMBER(BG16:BG22)*1)<2,"Need≥2",RSQ(IF(ISNUMBER(BG16:BG22),LN(BG16:BG22),FALSE),IF(ISNUMBER(BG16:BG22),LN(BF6:BF12),FALSE))),"N/A") | K27: =IFERROR(IF(SUMPRODUCT(ISNUMBER(BG16:BG22)*1)<3,"Need≥3",1-(1-(IFERROR(IF(SUMPRODUCT(ISNUMBER(BG16:BG22)*1)<2,"Need≥2",RSQ(IF(ISNUMBER(BG16:BG22),LN(BG16:BG22),FALSE),IF(ISNUMBER(BG16:BG22),LN(BF6:BF12),FALSE))),"N/A")))*(B27-1)/(B27-2)),"N/A") | L27: =IFERROR(IF(SUMPRODUCT(ISNUMBER(BG16:BG22)*1)<3,"Need≥3",SQRT((1-(IFERROR(IF(SUMPRODUCT(ISNUMBER(BG16:BG22)*1)<2,"Need≥2",RSQ(IF(ISNUMBER(BG16:BG22),LN(BG16:BG22),FALSE),IF(ISNUMBER(BG16:BG22),LN(BF6:BF12),FALSE))),"N/A")))*VAR(IF(ISNUMBER(BG16:BG22),LN(BG16:BG22),FALSE))/((B27-2)*VAR(IF(ISNUMBER(BG16:BG22),LN(BF6:BF12),FALSE))))),"N/A") | M27: =IF(ISNUMBER(F27),IF(F27<0.85,"⚠ Check fit","OK"),"")
A28: Fe | B28: =SUMPRODUCT((ISNUMBER(D16:D22)*1)) | C28: =IFERROR(IF(SUMPRODUCT(ISNUMBER(D16:D22)*1)<2,"Need≥2",EXP(INTERCEPT(IF(ISNUMBER(D16:D22),LN(D16:D22),FALSE),IF(ISNUMBER(D16:D22),LN(B6:B12),FALSE)))),"N/A") | D28: =IFERROR(IF(SUMPRODUCT(ISNUMBER(D16:D22)*1)<2,"Need≥2",SLOPE(IF(ISNUMBER(D16:D22),LN(D16:D22),FALSE),IF(ISNUMBER(D16:D22),LN(B6:B12),FALSE))),"N/A") | E28: =IFERROR(IF(SUMPRODUCT(ISNUMBER(D16:D22)*1)<2,"Need≥2",RSQ(IF(ISNUMBER(D16:D22),LN(D16:D22),FALSE),IF(ISNUMBER(D16:D22),LN(B6:B12),FALSE))),"N/A") | F28: =IFERROR(IF(SUMPRODUCT(ISNUMBER(D16:D22)*1)<3,"Need≥3",1-(1-(IFERROR(IF(SUMPRODUCT(ISNUMBER(D16:D22)*1)<2,"Need≥2",RSQ(IF(ISNUMBER(D16:D22),LN(D16:D22),FALSE),IF(ISNUMBER(D16:D22),LN(B6:B12),FALSE))),"N/A")))*(B28-1)/(B28-2)),"N/A") | G28: =IFERROR(IF(SUMPRODUCT(ISNUMBER(D16:D22)*1)<3,"Need≥3",SQRT((1-(IFERROR(IF(SUMPRODUCT(ISNUMBER(D16:D22)*1)<2,"Need≥2",RSQ(IF(ISNUMBER(D16:D22),LN(D16:D22),FALSE),IF(ISNUMBER(D16:D22),LN(B6:B12),FALSE))),"N/A")))*VAR(IF(ISNUMBER(D16:D22),LN(D16:D22),FALSE))/((B28-2)*VAR(IF(ISNUMBER(D16:D22),LN(B6:B12),FALSE))))),"N/A") | H28: =IFERROR(IF(SUMPRODUCT(ISNUMBER(BH16:BH22)*1)<2,"Need≥2",EXP(INTERCEPT(IF(ISNUMBER(BH16:BH22),LN(BH16:BH22),FALSE),IF(ISNUMBER(BH16:BH22),LN(BF6:BF12),FALSE)))),"N/A") | I28: =IFERROR(IF(SUMPRODUCT(ISNUMBER(BH16:BH22)*1)<2,"Need≥2",SLOPE(IF(ISNUMBER(BH16:BH22),LN(BH16:BH22),FALSE),IF(ISNUMBER(BH16:BH22),LN(BF6:BF12),FALSE))),"N/A") | J28: =IFERROR(IF(SUMPRODUCT(ISNUMBER(BH16:BH22)*1)<2,"Need≥2",RSQ(IF(ISNUMBER(BH16:BH22),LN(BH16:BH22),FALSE),IF(ISNUMBER(BH16:BH22),LN(BF6:BF12),FALSE))),"N/A") | K28: =IFERROR(IF(SUMPRODUCT(ISNUMBER(BH16:BH22)*1)<3,"Need≥3",1-(1-(IFERROR(IF(SUMPRODUCT(ISNUMBER(BH16:BH22)*1)<2,"Need≥2",RSQ(IF(ISNUMBER(BH16:BH22),LN(BH16:BH22),FALSE),IF(ISNUMBER(BH16:BH22),LN(BF6:BF12),FALSE))),"N/A")))*(B28-1)/(B28-2)),"N/A") | L28: =IFERROR(IF(SUMPRODUCT(ISNUMBER(BH16:BH22)*1)<3,"Need≥3",SQRT((1-(IFERROR(IF(SUMPRODUCT(ISNUMBER(BH16:BH22)*1)<2,"Need≥2",RSQ(IF(ISNUMBER(BH16:BH22),LN(BH16:BH22),FALSE),IF(ISNUMBER(BH16:BH22),LN(BF6:BF12),FALSE))),"N/A")))*VAR(IF(ISNUMBER(BH16:BH22),LN(BH16:BH22),FALSE))/((B28-2)*VAR(IF(ISNUMBER(BH16:BH22),LN(BF6:BF12),FALSE))))),"N/A") | M28: =IF(ISNUMBER(F28),IF(F28<0.85,"⚠ Check fit","OK"),"")
A29: Co | B29: =SUMPRODUCT((ISNUMBER(E16:E22)*1)) | C29: =IFERROR(IF(SUMPRODUCT(ISNUMBER(E16:E22)*1)<2,"Need≥2",EXP(INTERCEPT(IF(ISNUMBER(E16:E22),LN(E16:E22),FALSE),IF(ISNUMBER(E16:E22),LN(B6:B12),FALSE)))),"N/A") | D29: =IFERROR(IF(SUMPRODUCT(ISNUMBER(E16:E22)*1)<2,"Need≥2",SLOPE(IF(ISNUMBER(E16:E22),LN(E16:E22),FALSE),IF(ISNUMBER(E16:E22),LN(B6:B12),FALSE))),"N/A") | E29: =IFERROR(IF(SUMPRODUCT(ISNUMBER(E16:E22)*1)<2,"Need≥2",RSQ(IF(ISNUMBER(E16:E22),LN(E16:E22),FALSE),IF(ISNUMBER(E16:E22),LN(B6:B12),FALSE))),"N/A") | F29: =IFERROR(IF(SUMPRODUCT(ISNUMBER(E16:E22)*1)<3,"Need≥3",1-(1-(IFERROR(IF(SUMPRODUCT(ISNUMBER(E16:E22)*1)<2,"Need≥2",RSQ(IF(ISNUMBER(E16:E22),LN(E16:E22),FALSE),IF(ISNUMBER(E16:E22),LN(B6:B12),FALSE))),"N/A")))*(B29-1)/(B29-2)),"N/A") | G29: =IFERROR(IF(SUMPRODUCT(ISNUMBER(E16:E22)*1)<3,"Need≥3",SQRT((1-(IFERROR(IF(SUMPRODUCT(ISNUMBER(E16:E22)*1)<2,"Need≥2",RSQ(IF(ISNUMBER(E16:E22),LN(E16:E22),FALSE),IF(ISNUMBER(E16:E22),LN(B6:B12),FALSE))),"N/A")))*VAR(IF(ISNUMBER(E16:E22),LN(E16:E22),FALSE))/((B29-2)*VAR(IF(ISNUMBER(E16:E22),LN(B6:B12),FALSE))))),"N/A") | H29: =IFERROR(IF(SUMPRODUCT(ISNUMBER(BI16:BI22)*1)<2,"Need≥2",EXP(INTERCEPT(IF(ISNUMBER(BI16:BI22),LN(BI16:BI22),FALSE),IF(ISNUMBER(BI16:BI22),LN(BF6:BF12),FALSE)))),"N/A") | I29: =IFERROR(IF(SUMPRODUCT(ISNUMBER(BI16:BI22)*1)<2,"Need≥2",SLOPE(IF(ISNUMBER(BI16:BI22),LN(BI16:BI22),FALSE),IF(ISNUMBER(BI16:BI22),LN(BF6:BF12),FALSE))),"N/A") | J29: =IFERROR(IF(SUMPRODUCT(ISNUMBER(BI16:BI22)*1)<2,"Need≥2",RSQ(IF(ISNUMBER(BI16:BI22),LN(BI16:BI22),FALSE),IF(ISNUMBER(BI16:BI22),LN(BF6:BF12),FALSE))),"N/A") | K29: =IFERROR(IF(SUMPRODUCT(ISNUMBER(BI16:BI22)*1)<3,"Need≥3",1-(1-(IFERROR(IF(SUMPRODUCT(ISNUMBER(BI16:BI22)*1)<2,"Need≥2",RSQ(IF(ISNUMBER(BI16:BI22),LN(BI16:BI22),FALSE),IF(ISNUMBER(BI16:BI22),LN(BF6:BF12),FALSE))),"N/A")))*(B29-1)/(B29-2)),"N/A") | L29: =IFERROR(IF(SUMPRODUCT(ISNUMBER(BI16:BI22)*1)<3,"Need≥3",SQRT((1-(IFERROR(IF(SUMPRODUCT(ISNUMBER(BI16:BI22)*1)<2,"Need≥2",RSQ(IF(ISNUMBER(BI16:BI22),LN(BI16:BI22),FALSE),IF(ISNUMBER(BI16:BI22),LN(BF6:BF12),FALSE))),"N/A")))*VAR(IF(ISNUMBER(BI16:BI22),LN(BI16:BI22),FALSE))/((B29-2)*VAR(IF(ISNUMBER(BI16:BI22),LN(BF6:BF12),FALSE))))),"N/A") | M29: =IF(ISNUMBER(F29),IF(F29<0.85,"⚠ Check fit","OK"),"")
A30: Zn | B30: =SUMPRODUCT((ISNUMBER(F16:F22)*1)) | C30: =IFERROR(IF(SUMPRODUCT(ISNUMBER(F16:F22)*1)<2,"Need≥2",EXP(INTERCEPT(IF(ISNUMBER(F16:F22),LN(F16:F22),FALSE),IF(ISNUMBER(F16:F22),LN(B6:B12),FALSE)))),"N/A") | D30: =IFERROR(IF(SUMPRODUCT(ISNUMBER(F16:F22)*1)<2,"Need≥2",SLOPE(IF(ISNUMBER(F16:F22),LN(F16:F22),FALSE),IF(ISNUMBER(F16:F22),LN(B6:B12),FALSE))),"N/A") | E30: =IFERROR(IF(SUMPRODUCT(ISNUMBER(F16:F22)*1)<2,"Need≥2",RSQ(IF(ISNUMBER(F16:F22),LN(F16:F22),FALSE),IF(ISNUMBER(F16:F22),LN(B6:B12),FALSE))),"N/A") | F30: =IFERROR(IF(SUMPRODUCT(ISNUMBER(F16:F22)*1)<3,"Need≥3",1-(1-(IFERROR(IF(SUMPRODUCT(ISNUMBER(F16:F22)*1)<2,"Need≥2",RSQ(IF(ISNUMBER(F16:F22),LN(F16:F22),FALSE),IF(ISNUMBER(F16:F22),LN(B6:B12),FALSE))),"N/A")))*(B30-1)/(B30-2)),"N/A") | G30: =IFERROR(IF(SUMPRODUCT(ISNUMBER(F16:F22)*1)<3,"Need≥3",SQRT((1-(IFERROR(IF(SUMPRODUCT(ISNUMBER(F16:F22)*1)<2,"Need≥2",RSQ(IF(ISNUMBER(F16:F22),LN(F16:F22),FALSE),IF(ISNUMBER(F16:F22),LN(B6:B12),FALSE))),"N/A")))*VAR(IF(ISNUMBER(F16:F22),LN(F16:F22),FALSE))/((B30-2)*VAR(IF(ISNUMBER(F16:F22),LN(B6:B12),FALSE))))),"N/A") | H30: =IFERROR(IF(SUMPRODUCT(ISNUMBER(BJ16:BJ22)*1)<2,"Need≥2",EXP(INTERCEPT(IF(ISNUMBER(BJ16:BJ22),LN(BJ16:BJ22),FALSE),IF(ISNUMBER(BJ16:BJ22),LN(BF6:BF12),FALSE)))),"N/A") | I30: =IFERROR(IF(SUMPRODUCT(ISNUMBER(BJ16:BJ22)*1)<2,"Need≥2",SLOPE(IF(ISNUMBER(BJ16:BJ22),LN(BJ16:BJ22),FALSE),IF(ISNUMBER(BJ16:BJ22),LN(BF6:BF12),FALSE))),"N/A") | J30: =IFERROR(IF(SUMPRODUCT(ISNUMBER(BJ16:BJ22)*1)<2,"Need≥2",RSQ(IF(ISNUMBER(BJ16:BJ22),LN(BJ16:BJ22),FALSE),IF(ISNUMBER(BJ16:BJ22),LN(BF6:BF12),FALSE))),"N/A") | K30: =IFERROR(IF(SUMPRODUCT(ISNUMBER(BJ16:BJ22)*1)<3,"Need≥3",1-(1-(IFERROR(IF(SUMPRODUCT(ISNUMBER(BJ16:BJ22)*1)<2,"Need≥2",RSQ(IF(ISNUMBER(BJ16:BJ22),LN(BJ16:BJ22),FALSE),IF(ISNUMBER(BJ16:BJ22),LN(BF6:BF12),FALSE))),"N/A")))*(B30-1)/(B30-2)),"N/A") | L30: =IFERROR(IF(SUMPRODUCT(ISNUMBER(BJ16:BJ22)*1)<3,"Need≥3",SQRT((1-(IFERROR(IF(SUMPRODUCT(ISNUMBER(BJ16:BJ22)*1)<2,"Need≥2",RSQ(IF(ISNUMBER(BJ16:BJ22),LN(BJ16:BJ22),FALSE),IF(ISNUMBER(BJ16:BJ22),LN(BF6:BF12),FALSE))),"N/A")))*VAR(IF(ISNUMBER(BJ16:BJ22),LN(BJ16:BJ22),FALSE))/((B30-2)*VAR(IF(ISNUMBER(BJ16:BJ22),LN(BF6:BF12),FALSE))))),"N/A") | M30: =IF(ISNUMBER(F30),IF(F30<0.85,"⚠ Check fit","OK"),"")
A31: Ga | B31: =SUMPRODUCT((ISNUMBER(G16:G22)*1)) | C31: =IFERROR(IF(SUMPRODUCT(ISNUMBER(G16:G22)*1)<2,"Need≥2",EXP(INTERCEPT(IF(ISNUMBER(G16:G22),LN(G16:G22),FALSE),IF(ISNUMBER(G16:G22),LN(B6:B12),FALSE)))),"N/A") | D31: =IFERROR(IF(SUMPRODUCT(ISNUMBER(G16:G22)*1)<2,"Need≥2",SLOPE(IF(ISNUMBER(G16:G22),LN(G16:G22),FALSE),IF(ISNUMBER(G16:G22),LN(B6:B12),FALSE))),"N/A") | E31: =IFERROR(IF(SUMPRODUCT(ISNUMBER(G16:G22)*1)<2,"Need≥2",RSQ(IF(ISNUMBER(G16:G22),LN(G16:G22),FALSE),IF(ISNUMBER(G16:G22),LN(B6:B12),FALSE))),"N/A") | F31: =IFERROR(IF(SUMPRODUCT(ISNUMBER(G16:G22)*1)<3,"Need≥3",1-(1-(IFERROR(IF(SUMPRODUCT(ISNUMBER(G16:G22)*1)<2,"Need≥2",RSQ(IF(ISNUMBER(G16:G22),LN(G16:G22),FALSE),IF(ISNUMBER(G16:G22),LN(B6:B12),FALSE))),"N/A")))*(B31-1)/(B31-2)),"N/A") | G31: =IFERROR(IF(SUMPRODUCT(ISNUMBER(G16:G22)*1)<3,"Need≥3",SQRT((1-(IFERROR(IF(SUMPRODUCT(ISNUMBER(G16:G22)*1)<2,"Need≥2",RSQ(IF(ISNUMBER(G16:G22),LN(G16:G22),FALSE),IF(ISNUMBER(G16:G22),LN(B6:B12),FALSE))),"N/A")))*VAR(IF(ISNUMBER(G16:G22),LN(G16:G22),FALSE))/((B31-2)*VAR(IF(ISNUMBER(G16:G22),LN(B6:B12),FALSE))))),"N/A") | H31: =IFERROR(IF(SUMPRODUCT(ISNUMBER(BK16:BK22)*1)<2,"Need≥2",EXP(INTERCEPT(IF(ISNUMBER(BK16:BK22),LN(BK16:BK22),FALSE),IF(ISNUMBER(BK16:BK22),LN(BF6:BF12),FALSE)))),"N/A") | I31: =IFERROR(IF(SUMPRODUCT(ISNUMBER(BK16:BK22)*1)<2,"Need≥2",SLOPE(IF(ISNUMBER(BK16:BK22),LN(BK16:BK22),FALSE),IF(ISNUMBER(BK16:BK22),LN(BF6:BF12),FALSE))),"N/A") | J31: =IFERROR(IF(SUMPRODUCT(ISNUMBER(BK16:BK22)*1)<2,"Need≥2",RSQ(IF(ISNUMBER(BK16:BK22),LN(BK16:BK22),FALSE),IF(ISNUMBER(BK16:BK22),LN(BF6:BF12),FALSE))),"N/A") | K31: =IFERROR(IF(SUMPRODUCT(ISNUMBER(BK16:BK22)*1)<3,"Need≥3",1-(1-(IFERROR(IF(SUMPRODUCT(ISNUMBER(BK16:BK22)*1)<2,"Need≥2",RSQ(IF(ISNUMBER(BK16:BK22),LN(BK16:BK22),FALSE),IF(ISNUMBER(BK16:BK22),LN(BF6:BF12),FALSE))),"N/A")))*(B31-1)/(B31-2)),"N/A") | L31: =IFERROR(IF(SUMPRODUCT(ISNUMBER(BK16:BK22)*1)<3,"Need≥3",SQRT((1-(IFERROR(IF(SUMPRODUCT(ISNUMBER(BK16:BK22)*1)<2,"Need≥2",RSQ(IF(ISNUMBER(BK16:BK22),LN(BK16:BK22),FALSE),IF(ISNUMBER(BK16:BK22),LN(BF6:BF12),FALSE))),"N/A")))*VAR(IF(ISNUMBER(BK16:BK22),LN(BK16:BK22),FALSE))/((B31-2)*VAR(IF(ISNUMBER(BK16:BK22),LN(BF6:BF12),FALSE))))),"N/A") | M31: =IF(ISNUMBER(F31),IF(F31<0.85,"⚠ Check fit","OK"),"")
A32: Rb | B32: =SUMPRODUCT((ISNUMBER(H16:H22)*1)) | C32: =IFERROR(IF(SUMPRODUCT(ISNUMBER(H16:H22)*1)<2,"Need≥2",EXP(INTERCEPT(IF(ISNUMBER(H16:H22),LN(H16:H22),FALSE),IF(ISNUMBER(H16:H22),LN(B6:B12),FALSE)))),"N/A") | D32: =IFERROR(IF(SUMPRODUCT(ISNUMBER(H16:H22)*1)<2,"Need≥2",SLOPE(IF(ISNUMBER(H16:H22),LN(H16:H22),FALSE),IF(ISNUMBER(H16:H22),LN(B6:B12),FALSE))),"N/A") | E32: =IFERROR(IF(SUMPRODUCT(ISNUMBER(H16:H22)*1)<2,"Need≥2",RSQ(IF(ISNUMBER(H16:H22),LN(H16:H22),FALSE),IF(ISNUMBER(H16:H22),LN(B6:B12),FALSE))),"N/A") | F32: =IFERROR(IF(SUMPRODUCT(ISNUMBER(H16:H22)*1)<3,"Need≥3",1-(1-(IFERROR(IF(SUMPRODUCT(ISNUMBER(H16:H22)*1)<2,"Need≥2",RSQ(IF(ISNUMBER(H16:H22),LN(H16:H22),FALSE),IF(ISNUMBER(H16:H22),LN(B6:B12),FALSE))),"N/A")))*(B32-1)/(B32-2)),"N/A") | G32: =IFERROR(IF(SUMPRODUCT(ISNUMBER(H16:H22)*1)<3,"Need≥3",SQRT((1-(IFERROR(IF(SUMPRODUCT(ISNUMBER(H16:H22)*1)<2,"Need≥2",RSQ(IF(ISNUMBER(H16:H22),LN(H16:H22),FALSE),IF(ISNUMBER(H16:H22),LN(B6:B12),FALSE))),"N/A")))*VAR(IF(ISNUMBER(H16:H22),LN(H16:H22),FALSE))/((B32-2)*VAR(IF(ISNUMBER(H16:H22),LN(B6:B12),FALSE))))),"N/A") | H32: =IFERROR(IF(SUMPRODUCT(ISNUMBER(BL16:BL22)*1)<2,"Need≥2",EXP(INTERCEPT(IF(ISNUMBER(BL16:BL22),LN(BL16:BL22),FALSE),IF(ISNUMBER(BL16:BL22),LN(BF6:BF12),FALSE)))),"N/A") | I32: =IFERROR(IF(SUMPRODUCT(ISNUMBER(BL16:BL22)*1)<2,"Need≥2",SLOPE(IF(ISNUMBER(BL16:BL22),LN(BL16:BL22),FALSE),IF(ISNUMBER(BL16:BL22),LN(BF6:BF12),FALSE))),"N/A") | J32: =IFERROR(IF(SUMPRODUCT(ISNUMBER(BL16:BL22)*1)<2,"Need≥2",RSQ(IF(ISNUMBER(BL16:BL22),LN(BL16:BL22),FALSE),IF(ISNUMBER(BL16:BL22),LN(BF6:BF12),FALSE))),"N/A") | K32: =IFERROR(IF(SUMPRODUCT(ISNUMBER(BL16:BL22)*1)<3,"Need≥3",1-(1-(IFERROR(IF(SUMPRODUCT(ISNUMBER(BL16:BL22)*1)<2,"Need≥2",RSQ(IF(ISNUMBER(BL16:BL22),LN(BL16:BL22),FALSE),IF(ISNUMBER(BL16:BL22),LN(BF6:BF12),FALSE))),"N/A")))*(B32-1)/(B32-2)),"N/A") | L32: =IFERROR(IF(SUMPRODUCT(ISNUMBER(BL16:BL22)*1)<3,"Need≥3",SQRT((1-(IFERROR(IF(SUMPRODUCT(ISNUMBER(BL16:BL22)*1)<2,"Need≥2",RSQ(IF(ISNUMBER(BL16:BL22),LN(BL16:BL22),FALSE),IF(ISNUMBER(BL16:BL22),LN(BF6:BF12),FALSE))),"N/A")))*VAR(IF(ISNUMBER(BL16:BL22),LN(BL16:BL22),FALSE))/((B32-2)*VAR(IF(ISNUMBER(BL16:BL22),LN(BF6:BF12),FALSE))))),"N/A") | M32: =IF(ISNUMBER(F32),IF(F32<0.85,"⚠ Check fit","OK"),"")
A33: Y | B33: =SUMPRODUCT((ISNUMBER(I16:I22)*1)) | C33: =IFERROR(IF(SUMPRODUCT(ISNUMBER(I16:I22)*1)<2,"Need≥2",EXP(INTERCEPT(IF(ISNUMBER(I16:I22),LN(I16:I22),FALSE),IF(ISNUMBER(I16:I22),LN(B6:B12),FALSE)))),"N/A") | D33: =IFERROR(IF(SUMPRODUCT(ISNUMBER(I16:I22)*1)<2,"Need≥2",SLOPE(IF(ISNUMBER(I16:I22),LN(I16:I22),FALSE),IF(ISNUMBER(I16:I22),LN(B6:B12),FALSE))),"N/A") | E33: =IFERROR(IF(SUMPRODUCT(ISNUMBER(I16:I22)*1)<2,"Need≥2",RSQ(IF(ISNUMBER(I16:I22),LN(I16:I22),FALSE),IF(ISNUMBER(I16:I22),LN(B6:B12),FALSE))),"N/A") | F33: =IFERROR(IF(SUMPRODUCT(ISNUMBER(I16:I22)*1)<3,"Need≥3",1-(1-(IFERROR(IF(SUMPRODUCT(ISNUMBER(I16:I22)*1)<2,"Need≥2",RSQ(IF(ISNUMBER(I16:I22),LN(I16:I22),FALSE),IF(ISNUMBER(I16:I22),LN(B6:B12),FALSE))),"N/A")))*(B33-1)/(B33-2)),"N/A") | G33: =IFERROR(IF(SUMPRODUCT(ISNUMBER(I16:I22)*1)<3,"Need≥3",SQRT((1-(IFERROR(IF(SUMPRODUCT(ISNUMBER(I16:I22)*1)<2,"Need≥2",RSQ(IF(ISNUMBER(I16:I22),LN(I16:I22),FALSE),IF(ISNUMBER(I16:I22),LN(B6:B12),FALSE))),"N/A")))*VAR(IF(ISNUMBER(I16:I22),LN(I16:I22),FALSE))/((B33-2)*VAR(IF(ISNUMBER(I16:I22),LN(B6:B12),FALSE))))),"N/A") | H33: =IFERROR(IF(SUMPRODUCT(ISNUMBER(BM16:BM22)*1)<2,"Need≥2",EXP(INTERCEPT(IF(ISNUMBER(BM16:BM22),LN(BM16:BM22),FALSE),IF(ISNUMBER(BM16:BM22),LN(BF6:BF12),FALSE)))),"N/A") | I33: =IFERROR(IF(SUMPRODUCT(ISNUMBER(BM16:BM22)*1)<2,"Need≥2",SLOPE(IF(ISNUMBER(BM16:BM22),LN(BM16:BM22),FALSE),IF(ISNUMBER(BM16:BM22),LN(BF6:BF12),FALSE))),"N/A") | J33: =IFERROR(IF(SUMPRODUCT(ISNUMBER(BM16:BM22)*1)<2,"Need≥2",RSQ(IF(ISNUMBER(BM16:BM22),LN(BM16:BM22),FALSE),IF(ISNUMBER(BM16:BM22),LN(BF6:BF12),FALSE))),"N/A") | K33: =IFERROR(IF(SUMPRODUCT(ISNUMBER(BM16:BM22)*1)<3,"Need≥3",1-(1-(IFERROR(IF(SUMPRODUCT(ISNUMBER(BM16:BM22)*1)<2,"Need≥2",RSQ(IF(ISNUMBER(BM16:BM22),LN(BM16:BM22),FALSE),IF(ISNUMBER(BM16:BM22),LN(BF6:BF12),FALSE))),"N/A")))*(B33-1)/(B33-2)),"N/A") | L33: =IFERROR(IF(SUMPRODUCT(ISNUMBER(BM16:BM22)*1)<3,"Need≥3",SQRT((1-(IFERROR(IF(SUMPRODUCT(ISNUMBER(BM16:BM22)*1)<2,"Need≥2",RSQ(IF(ISNUMBER(BM16:BM22),LN(BM16:BM22),FALSE),IF(ISNUMBER(BM16:BM22),LN(BF6:BF12),FALSE))),"N/A")))*VAR(IF(ISNUMBER(BM16:BM22),LN(BM16:BM22),FALSE))/((B33-2)*VAR(IF(ISNUMBER(BM16:BM22),LN(BF6:BF12),FALSE))))),"N/A") | M33: =IF(ISNUMBER(F33),IF(F33<0.85,"⚠ Check fit","OK"),"")
A34: Zr | B34: =SUMPRODUCT((ISNUMBER(J16:J22)*1)) | C34: =IFERROR(IF(SUMPRODUCT(ISNUMBER(J16:J22)*1)<2,"Need≥2",EXP(INTERCEPT(IF(ISNUMBER(J16:J22),LN(J16:J22),FALSE),IF(ISNUMBER(J16:J22),LN(B6:B12),FALSE)))),"N/A") | D34: =IFERROR(IF(SUMPRODUCT(ISNUMBER(J16:J22)*1)<2,"Need≥2",SLOPE(IF(ISNUMBER(J16:J22),LN(J16:J22),FALSE),IF(ISNUMBER(J16:J22),LN(B6:B12),FALSE))),"N/A") | E34: =IFERROR(IF(SUMPRODUCT(ISNUMBER(J16:J22)*1)<2,"Need≥2",RSQ(IF(ISNUMBER(J16:J22),LN(J16:J22),FALSE),IF(ISNUMBER(J16:J22),LN(B6:B12),FALSE))),"N/A") | F34: =IFERROR(IF(SUMPRODUCT(ISNUMBER(J16:J22)*1)<3,"Need≥3",1-(1-(IFERROR(IF(SUMPRODUCT(ISNUMBER(J16:J22)*1)<2,"Need≥2",RSQ(IF(ISNUMBER(J16:J22),LN(J16:J22),FALSE),IF(ISNUMBER(J16:J22),LN(B6:B12),FALSE))),"N/A")))*(B34-1)/(B34-2)),"N/A") | G34: =IFERROR(IF(SUMPRODUCT(ISNUMBER(J16:J22)*1)<3,"Need≥3",SQRT((1-(IFERROR(IF(SUMPRODUCT(ISNUMBER(J16:J22)*1)<2,"Need≥2",RSQ(IF(ISNUMBER(J16:J22),LN(J16:J22),FALSE),IF(ISNUMBER(J16:J22),LN(B6:B12),FALSE))),"N/A")))*VAR(IF(ISNUMBER(J16:J22),LN(J16:J22),FALSE))/((B34-2)*VAR(IF(ISNUMBER(J16:J22),LN(B6:B12),FALSE))))),"N/A") | H34: =IFERROR(IF(SUMPRODUCT(ISNUMBER(BN16:BN22)*1)<2,"Need≥2",EXP(INTERCEPT(IF(ISNUMBER(BN16:BN22),LN(BN16:BN22),FALSE),IF(ISNUMBER(BN16:BN22),LN(BF6:BF12),FALSE)))),"N/A") | I34: =IFERROR(IF(SUMPRODUCT(ISNUMBER(BN16:BN22)*1)<2,"Need≥2",SLOPE(IF(ISNUMBER(BN16:BN22),LN(BN16:BN22),FALSE),IF(ISNUMBER(BN16:BN22),LN(BF6:BF12),FALSE))),"N/A") | J34: =IFERROR(IF(SUMPRODUCT(ISNUMBER(BN16:BN22)*1)<2,"Need≥2",RSQ(IF(ISNUMBER(BN16:BN22),LN(BN16:BN22),FALSE),IF(ISNUMBER(BN16:BN22),LN(BF6:BF12),FALSE))),"N/A") | K34: =IFERROR(IF(SUMPRODUCT(ISNUMBER(BN16:BN22)*1)<3,"Need≥3",1-(1-(IFERROR(IF(SUMPRODUCT(ISNUMBER(BN16:BN22)*1)<2,"Need≥2",RSQ(IF(ISNUMBER(BN16:BN22),LN(BN16:BN22),FALSE),IF(ISNUMBER(BN16:BN22),LN(BF6:BF12),FALSE))),"N/A")))*(B34-1)/(B34-2)),"N/A") | L34: =IFERROR(IF(SUMPRODUCT(ISNUMBER(BN16:BN22)*1)<3,"Need≥3",SQRT((1-(IFERROR(IF(SUMPRODUCT(ISNUMBER(BN16:BN22)*1)<2,"Need≥2",RSQ(IF(ISNUMBER(BN16:BN22),LN(BN16:BN22),FALSE),IF(ISNUMBER(BN16:BN22),LN(BF6:BF12),FALSE))),"N/A")))*VAR(IF(ISNUMBER(BN16:BN22),LN(BN16:BN22),FALSE))/((B34-2)*VAR(IF(ISNUMBER(BN16:BN22),LN(BF6:BF12),FALSE))))),"N/A") | M34: =IF(ISNUMBER(F34),IF(F34<0.85,"⚠ Check fit","OK"),"")
A35: La | B35: =SUMPRODUCT((ISNUMBER(K16:K22)*1)) | C35: =IFERROR(IF(SUMPRODUCT(ISNUMBER(K16:K22)*1)<2,"Need≥2",EXP(INTERCEPT(IF(ISNUMBER(K16:K22),LN(K16:K22),FALSE),IF(ISNUMBER(K16:K22),LN(B6:B12),FALSE)))),"N/A") | D35: =IFERROR(IF(SUMPRODUCT(ISNUMBER(K16:K22)*1)<2,"Need≥2",SLOPE(IF(ISNUMBER(K16:K22),LN(K16:K22),FALSE),IF(ISNUMBER(K16:K22),LN(B6:B12),FALSE))),"N/A") | E35: =IFERROR(IF(SUMPRODUCT(ISNUMBER(K16:K22)*1)<2,"Need≥2",RSQ(IF(ISNUMBER(K16:K22),LN(K16:K22),FALSE),IF(ISNUMBER(K16:K22),LN(B6:B12),FALSE))),"N/A") | F35: =IFERROR(IF(SUMPRODUCT(ISNUMBER(K16:K22)*1)<3,"Need≥3",1-(1-(IFERROR(IF(SUMPRODUCT(ISNUMBER(K16:K22)*1)<2,"Need≥2",RSQ(IF(ISNUMBER(K16:K22),LN(K16:K22),FALSE),IF(ISNUMBER(K16:K22),LN(B6:B12),FALSE))),"N/A")))*(B35-1)/(B35-2)),"N/A") | G35: =IFERROR(IF(SUMPRODUCT(ISNUMBER(K16:K22)*1)<3,"Need≥3",SQRT((1-(IFERROR(IF(SUMPRODUCT(ISNUMBER(K16:K22)*1)<2,"Need≥2",RSQ(IF(ISNUMBER(K16:K22),LN(K16:K22),FALSE),IF(ISNUMBER(K16:K22),LN(B6:B12),FALSE))),"N/A")))*VAR(IF(ISNUMBER(K16:K22),LN(K16:K22),FALSE))/((B35-2)*VAR(IF(ISNUMBER(K16:K22),LN(B6:B12),FALSE))))),"N/A") | H35: =IFERROR(IF(SUMPRODUCT(ISNUMBER(BO16:BO22)*1)<2,"Need≥2",EXP(INTERCEPT(IF(ISNUMBER(BO16:BO22),LN(BO16:BO22),FALSE),IF(ISNUMBER(BO16:BO22),LN(BF6:BF12),FALSE)))),"N/A") | I35: =IFERROR(IF(SUMPRODUCT(ISNUMBER(BO16:BO22)*1)<2,"Need≥2",SLOPE(IF(ISNUMBER(BO16:BO22),LN(BO16:BO22),FALSE),IF(ISNUMBER(BO16:BO22),LN(BF6:BF12),FALSE))),"N/A") | J35: =IFERROR(IF(SUMPRODUCT(ISNUMBER(BO16:BO22)*1)<2,"Need≥2",RSQ(IF(ISNUMBER(BO16:BO22),LN(BO16:BO22),FALSE),IF(ISNUMBER(BO16:BO22),LN(BF6:BF12),FALSE))),"N/A") | K35: =IFERROR(IF(SUMPRODUCT(ISNUMBER(BO16:BO22)*1)<3,"Need≥3",1-(1-(IFERROR(IF(SUMPRODUCT(ISNUMBER(BO16:BO22)*1)<2,"Need≥2",RSQ(IF(ISNUMBER(BO16:BO22),LN(BO16:BO22),FALSE),IF(ISNUMBER(BO16:BO22),LN(BF6:BF12),FALSE))),"N/A")))*(B35-1)/(B35-2)),"N/A") | L35: =IFERROR(IF(SUMPRODUCT(ISNUMBER(BO16:BO22)*1)<3,"Need≥3",SQRT((1-(IFERROR(IF(SUMPRODUCT(ISNUMBER(BO16:BO22)*1)<2,"Need≥2",RSQ(IF(ISNUMBER(BO16:BO22),LN(BO16:BO22),FALSE),IF(ISNUMBER(BO16:BO22),LN(BF6:BF12),FALSE))),"N/A")))*VAR(IF(ISNUMBER(BO16:BO22),LN(BO16:BO22),FALSE))/((B35-2)*VAR(IF(ISNUMBER(BO16:BO22),LN(BF6:BF12),FALSE))))),"N/A") | M35: =IF(ISNUMBER(F35),IF(F35<0.85,"⚠ Check fit","OK"),"")
A36: Ce | B36: =SUMPRODUCT((ISNUMBER(L16:L22)*1)) | C36: =IFERROR(IF(SUMPRODUCT(ISNUMBER(L16:L22)*1)<2,"Need≥2",EXP(INTERCEPT(IF(ISNUMBER(L16:L22),LN(L16:L22),FALSE),IF(ISNUMBER(L16:L22),LN(B6:B12),FALSE)))),"N/A") | D36: =IFERROR(IF(SUMPRODUCT(ISNUMBER(L16:L22)*1)<2,"Need≥2",SLOPE(IF(ISNUMBER(L16:L22),LN(L16:L22),FALSE),IF(ISNUMBER(L16:L22),LN(B6:B12),FALSE))),"N/A") | E36: =IFERROR(IF(SUMPRODUCT(ISNUMBER(L16:L22)*1)<2,"Need≥2",RSQ(IF(ISNUMBER(L16:L22),LN(L16:L22),FALSE),IF(ISNUMBER(L16:L22),LN(B6:B12),FALSE))),"N/A") | F36: =IFERROR(IF(SUMPRODUCT(ISNUMBER(L16:L22)*1)<3,"Need≥3",1-(1-(IFERROR(IF(SUMPRODUCT(ISNUMBER(L16:L22)*1)<2,"Need≥2",RSQ(IF(ISNUMBER(L16:L22),LN(L16:L22),FALSE),IF(ISNUMBER(L16:L22),LN(B6:B12),FALSE))),"N/A")))*(B36-1)/(B36-2)),"N/A") | G36: =IFERROR(IF(SUMPRODUCT(ISNUMBER(L16:L22)*1)<3,"Need≥3",SQRT((1-(IFERROR(IF(SUMPRODUCT(ISNUMBER(L16:L22)*1)<2,"Need≥2",RSQ(IF(ISNUMBER(L16:L22),LN(L16:L22),FALSE),IF(ISNUMBER(L16:L22),LN(B6:B12),FALSE))),"N/A")))*VAR(IF(ISNUMBER(L16:L22),LN(L16:L22),FALSE))/((B36-2)*VAR(IF(ISNUMBER(L16:L22),LN(B6:B12),FALSE))))),"N/A") | H36: =IFERROR(IF(SUMPRODUCT(ISNUMBER(BP16:BP22)*1)<2,"Need≥2",EXP(INTERCEPT(IF(ISNUMBER(BP16:BP22),LN(BP16:BP22),FALSE),IF(ISNUMBER(BP16:BP22),LN(BF6:BF12),FALSE)))),"N/A") | I36: =IFERROR(IF(SUMPRODUCT(ISNUMBER(BP16:BP22)*1)<2,"Need≥2",SLOPE(IF(ISNUMBER(BP16:BP22),LN(BP16:BP22),FALSE),IF(ISNUMBER(BP16:BP22),LN(BF6:BF12),FALSE))),"N/A") | J36: =IFERROR(IF(SUMPRODUCT(ISNUMBER(BP16:BP22)*1)<2,"Need≥2",RSQ(IF(ISNUMBER(BP16:BP22),LN(BP16:BP22),FALSE),IF(ISNUMBER(BP16:BP22),LN(BF6:BF12),FALSE))),"N/A") | K36: =IFERROR(IF(SUMPRODUCT(ISNUMBER(BP16:BP22)*1)<3,"Need≥3",1-(1-(IFERROR(IF(SUMPRODUCT(ISNUMBER(BP16:BP22)*1)<2,"Need≥2",RSQ(IF(ISNUMBER(BP16:BP22),LN(BP16:BP22),FALSE),IF(ISNUMBER(BP16:BP22),LN(BF6:BF12),FALSE))),"N/A")))*(B36-1)/(B36-2)),"N/A") | L36: =IFERROR(IF(SUMPRODUCT(ISNUMBER(BP16:BP22)*1)<3,"Need≥3",SQRT((1-(IFERROR(IF(SUMPRODUCT(ISNUMBER(BP16:BP22)*1)<2,"Need≥2",RSQ(IF(ISNUMBER(BP16:BP22),LN(BP16:BP22),FALSE),IF(ISNUMBER(BP16:BP22),LN(BF6:BF12),FALSE))),"N/A")))*VAR(IF(ISNUMBER(BP16:BP22),LN(BP16:BP22),FALSE))/((B36-2)*VAR(IF(ISNUMBER(BP16:BP22),LN(BF6:BF12),FALSE))))),"N/A") | M36: =IF(ISNUMBER(F36),IF(F36<0.85,"⚠ Check fit","OK"),"")
A37: Pr | B37: =SUMPRODUCT((ISNUMBER(M16:M22)*1)) | C37: =IFERROR(IF(SUMPRODUCT(ISNUMBER(M16:M22)*1)<2,"Need≥2",EXP(INTERCEPT(IF(ISNUMBER(M16:M22),LN(M16:M22),FALSE),IF(ISNUMBER(M16:M22),LN(B6:B12),FALSE)))),"N/A") | D37: =IFERROR(IF(SUMPRODUCT(ISNUMBER(M16:M22)*1)<2,"Need≥2",SLOPE(IF(ISNUMBER(M16:M22),LN(M16:M22),FALSE),IF(ISNUMBER(M16:M22),LN(B6:B12),FALSE))),"N/A") | E37: =IFERROR(IF(SUMPRODUCT(ISNUMBER(M16:M22)*1)<2,"Need≥2",RSQ(IF(ISNUMBER(M16:M22),LN(M16:M22),FALSE),IF(ISNUMBER(M16:M22),LN(B6:B12),FALSE))),"N/A") | F37: =IFERROR(IF(SUMPRODUCT(ISNUMBER(M16:M22)*1)<3,"Need≥3",1-(1-(IFERROR(IF(SUMPRODUCT(ISNUMBER(M16:M22)*1)<2,"Need≥2",RSQ(IF(ISNUMBER(M16:M22),LN(M16:M22),FALSE),IF(ISNUMBER(M16:M22),LN(B6:B12),FALSE))),"N/A")))*(B37-1)/(B37-2)),"N/A") | G37: =IFERROR(IF(SUMPRODUCT(ISNUMBER(M16:M22)*1)<3,"Need≥3",SQRT((1-(IFERROR(IF(SUMPRODUCT(ISNUMBER(M16:M22)*1)<2,"Need≥2",RSQ(IF(ISNUMBER(M16:M22),LN(M16:M22),FALSE),IF(ISNUMBER(M16:M22),LN(B6:B12),FALSE))),"N/A")))*VAR(IF(ISNUMBER(M16:M22),LN(M16:M22),FALSE))/((B37-2)*VAR(IF(ISNUMBER(M16:M22),LN(B6:B12),FALSE))))),"N/A") | H37: =IFERROR(IF(SUMPRODUCT(ISNUMBER(BQ16:BQ22)*1)<2,"Need≥2",EXP(INTERCEPT(IF(ISNUMBER(BQ16:BQ22),LN(BQ16:BQ22),FALSE),IF(ISNUMBER(BQ16:BQ22),LN(BF6:BF12),FALSE)))),"N/A") | I37: =IFERROR(IF(SUMPRODUCT(ISNUMBER(BQ16:BQ22)*1)<2,"Need≥2",SLOPE(IF(ISNUMBER(BQ16:BQ22),LN(BQ16:BQ22),FALSE),IF(ISNUMBER(BQ16:BQ22),LN(BF6:BF12),FALSE))),"N/A") | J37: =IFERROR(IF(SUMPRODUCT(ISNUMBER(BQ16:BQ22)*1)<2,"Need≥2",RSQ(IF(ISNUMBER(BQ16:BQ22),LN(BQ16:BQ22),FALSE),IF(ISNUMBER(BQ16:BQ22),LN(BF6:BF12),FALSE))),"N/A") | K37: =IFERROR(IF(SUMPRODUCT(ISNUMBER(BQ16:BQ22)*1)<3,"Need≥3",1-(1-(IFERROR(IF(SUMPRODUCT(ISNUMBER(BQ16:BQ22)*1)<2,"Need≥2",RSQ(IF(ISNUMBER(BQ16:BQ22),LN(BQ16:BQ22),FALSE),IF(ISNUMBER(BQ16:BQ22),LN(BF6:BF12),FALSE))),"N/A")))*(B37-1)/(B37-2)),"N/A") | L37: =IFERROR(IF(SUMPRODUCT(ISNUMBER(BQ16:BQ22)*1)<3,"Need≥3",SQRT((1-(IFERROR(IF(SUMPRODUCT(ISNUMBER(BQ16:BQ22)*1)<2,"Need≥2",RSQ(IF(ISNUMBER(BQ16:BQ22),LN(BQ16:BQ22),FALSE),IF(ISNUMBER(BQ16:BQ22),LN(BF6:BF12),FALSE))),"N/A")))*VAR(IF(ISNUMBER(BQ16:BQ22),LN(BQ16:BQ22),FALSE))/((B37-2)*VAR(IF(ISNUMBER(BQ16:BQ22),LN(BF6:BF12),FALSE))))),"N/A") | M37: =IF(ISNUMBER(F37),IF(F37<0.85,"⚠ Check fit","OK"),"")
A38: Nd | B38: =SUMPRODUCT((ISNUMBER(N16:N22)*1)) | C38: =IFERROR(IF(SUMPRODUCT(ISNUMBER(N16:N22)*1)<2,"Need≥2",EXP(INTERCEPT(IF(ISNUMBER(N16:N22),LN(N16:N22),FALSE),IF(ISNUMBER(N16:N22),LN(B6:B12),FALSE)))),"N/A") | D38: =IFERROR(IF(SUMPRODUCT(ISNUMBER(N16:N22)*1)<2,"Need≥2",SLOPE(IF(ISNUMBER(N16:N22),LN(N16:N22),FALSE),IF(ISNUMBER(N16:N22),LN(B6:B12),FALSE))),"N/A") | E38: =IFERROR(IF(SUMPRODUCT(ISNUMBER(N16:N22)*1)<2,"Need≥2",RSQ(IF(ISNUMBER(N16:N22),LN(N16:N22),FALSE),IF(ISNUMBER(N16:N22),LN(B6:B12),FALSE))),"N/A") | F38: =IFERROR(IF(SUMPRODUCT(ISNUMBER(N16:N22)*1)<3,"Need≥3",1-(1-(IFERROR(IF(SUMPRODUCT(ISNUMBER(N16:N22)*1)<2,"Need≥2",RSQ(IF(ISNUMBER(N16:N22),LN(N16:N22),FALSE),IF(ISNUMBER(N16:N22),LN(B6:B12),FALSE))),"N/A")))*(B38-1)/(B38-2)),"N/A") | G38: =IFERROR(IF(SUMPRODUCT(ISNUMBER(N16:N22)*1)<3,"Need≥3",SQRT((1-(IFERROR(IF(SUMPRODUCT(ISNUMBER(N16:N22)*1)<2,"Need≥2",RSQ(IF(ISNUMBER(N16:N22),LN(N16:N22),FALSE),IF(ISNUMBER(N16:N22),LN(B6:B12),FALSE))),"N/A")))*VAR(IF(ISNUMBER(N16:N22),LN(N16:N22),FALSE))/((B38-2)*VAR(IF(ISNUMBER(N16:N22),LN(B6:B12),FALSE))))),"N/A") | H38: =IFERROR(IF(SUMPRODUCT(ISNUMBER(BR16:BR22)*1)<2,"Need≥2",EXP(INTERCEPT(IF(ISNUMBER(BR16:BR22),LN(BR16:BR22),FALSE),IF(ISNUMBER(BR16:BR22),LN(BF6:BF12),FALSE)))),"N/A") | I38: =IFERROR(IF(SUMPRODUCT(ISNUMBER(BR16:BR22)*1)<2,"Need≥2",SLOPE(IF(ISNUMBER(BR16:BR22),LN(BR16:BR22),FALSE),IF(ISNUMBER(BR16:BR22),LN(BF6:BF12),FALSE))),"N/A") | J38: =IFERROR(IF(SUMPRODUCT(ISNUMBER(BR16:BR22)*1)<2,"Need≥2",RSQ(IF(ISNUMBER(BR16:BR22),LN(BR16:BR22),FALSE),IF(ISNUMBER(BR16:BR22),LN(BF6:BF12),FALSE))),"N/A") | K38: =IFERROR(IF(SUMPRODUCT(ISNUMBER(BR16:BR22)*1)<3,"Need≥3",1-(1-(IFERROR(IF(SUMPRODUCT(ISNUMBER(BR16:BR22)*1)<2,"Need≥2",RSQ(IF(ISNUMBER(BR16:BR22),LN(BR16:BR22),FALSE),IF(ISNUMBER(BR16:BR22),LN(BF6:BF12),FALSE))),"N/A")))*(B38-1)/(B38-2)),"N/A") | L38: =IFERROR(IF(SUMPRODUCT(ISNUMBER(BR16:BR22)*1)<3,"Need≥3",SQRT((1-(IFERROR(IF(SUMPRODUCT(ISNUMBER(BR16:BR22)*1)<2,"Need≥2",RSQ(IF(ISNUMBER(BR16:BR22),LN(BR16:BR22),FALSE),IF(ISNUMBER(BR16:BR22),LN(BF6:BF12),FALSE))),"N/A")))*VAR(IF(ISNUMBER(BR16:BR22),LN(BR16:BR22),FALSE))/((B38-2)*VAR(IF(ISNUMBER(BR16:BR22),LN(BF6:BF12),FALSE))))),"N/A") | M38: =IF(ISNUMBER(F38),IF(F38<0.85,"⚠ Check fit","OK"),"")
A39: Sm | B39: =SUMPRODUCT((ISNUMBER(O16:O22)*1)) | C39: =IFERROR(IF(SUMPRODUCT(ISNUMBER(O16:O22)*1)<2,"Need≥2",EXP(INTERCEPT(IF(ISNUMBER(O16:O22),LN(O16:O22),FALSE),IF(ISNUMBER(O16:O22),LN(B6:B12),FALSE)))),"N/A") | D39: =IFERROR(IF(SUMPRODUCT(ISNUMBER(O16:O22)*1)<2,"Need≥2",SLOPE(IF(ISNUMBER(O16:O22),LN(O16:O22),FALSE),IF(ISNUMBER(O16:O22),LN(B6:B12),FALSE))),"N/A") | E39: =IFERROR(IF(SUMPRODUCT(ISNUMBER(O16:O22)*1)<2,"Need≥2",RSQ(IF(ISNUMBER(O16:O22),LN(O16:O22),FALSE),IF(ISNUMBER(O16:O22),LN(B6:B12),FALSE))),"N/A") | F39: =IFERROR(IF(SUMPRODUCT(ISNUMBER(O16:O22)*1)<3,"Need≥3",1-(1-(IFERROR(IF(SUMPRODUCT(ISNUMBER(O16:O22)*1)<2,"Need≥2",RSQ(IF(ISNUMBER(O16:O22),LN(O16:O22),FALSE),IF(ISNUMBER(O16:O22),LN(B6:B12),FALSE))),"N/A")))*(B39-1)/(B39-2)),"N/A") | G39: =IFERROR(IF(SUMPRODUCT(ISNUMBER(O16:O22)*1)<3,"Need≥3",SQRT((1-(IFERROR(IF(SUMPRODUCT(ISNUMBER(O16:O22)*1)<2,"Need≥2",RSQ(IF(ISNUMBER(O16:O22),LN(O16:O22),FALSE),IF(ISNUMBER(O16:O22),LN(B6:B12),FALSE))),"N/A")))*VAR(IF(ISNUMBER(O16:O22),LN(O16:O22),FALSE))/((B39-2)*VAR(IF(ISNUMBER(O16:O22),LN(B6:B12),FALSE))))),"N/A") | H39: =IFERROR(IF(SUMPRODUCT(ISNUMBER(BS16:BS22)*1)<2,"Need≥2",EXP(INTERCEPT(IF(ISNUMBER(BS16:BS22),LN(BS16:BS22),FALSE),IF(ISNUMBER(BS16:BS22),LN(BF6:BF12),FALSE)))),"N/A") | I39: =IFERROR(IF(SUMPRODUCT(ISNUMBER(BS16:BS22)*1)<2,"Need≥2",SLOPE(IF(ISNUMBER(BS16:BS22),LN(BS16:BS22),FALSE),IF(ISNUMBER(BS16:BS22),LN(BF6:BF12),FALSE))),"N/A") | J39: =IFERROR(IF(SUMPRODUCT(ISNUMBER(BS16:BS22)*1)<2,"Need≥2",RSQ(IF(ISNUMBER(BS16:BS22),LN(BS16:BS22),FALSE),IF(ISNUMBER(BS16:BS22),LN(BF6:BF12),FALSE))),"N/A") | K39: =IFERROR(IF(SUMPRODUCT(ISNUMBER(BS16:BS22)*1)<3,"Need≥3",1-(1-(IFERROR(IF(SUMPRODUCT(ISNUMBER(BS16:BS22)*1)<2,"Need≥2",RSQ(IF(ISNUMBER(BS16:BS22),LN(BS16:BS22),FALSE),IF(ISNUMBER(BS16:BS22),LN(BF6:BF12),FALSE))),"N/A")))*(B39-1)/(B39-2)),"N/A") | L39: =IFERROR(IF(SUMPRODUCT(ISNUMBER(BS16:BS22)*1)<3,"Need≥3",SQRT((1-(IFERROR(IF(SUMPRODUCT(ISNUMBER(BS16:BS22)*1)<2,"Need≥2",RSQ(IF(ISNUMBER(BS16:BS22),LN(BS16:BS22),FALSE),IF(ISNUMBER(BS16:BS22),LN(BF6:BF12),FALSE))),"N/A")))*VAR(IF(ISNUMBER(BS16:BS22),LN(BS16:BS22),FALSE))/((B39-2)*VAR(IF(ISNUMBER(BS16:BS22),LN(BF6:BF12),FALSE))))),"N/A") | M39: =IF(ISNUMBER(F39),IF(F39<0.85,"⚠ Check fit","OK"),"")
A40: Eu | B40: =SUMPRODUCT((ISNUMBER(P16:P22)*1)) | C40: =IFERROR(IF(SUMPRODUCT(ISNUMBER(P16:P22)*1)<2,"Need≥2",EXP(INTERCEPT(IF(ISNUMBER(P16:P22),LN(P16:P22),FALSE),IF(ISNUMBER(P16:P22),LN(B6:B12),FALSE)))),"N/A") | D40: =IFERROR(IF(SUMPRODUCT(ISNUMBER(P16:P22)*1)<2,"Need≥2",SLOPE(IF(ISNUMBER(P16:P22),LN(P16:P22),FALSE),IF(ISNUMBER(P16:P22),LN(B6:B12),FALSE))),"N/A") | E40: =IFERROR(IF(SUMPRODUCT(ISNUMBER(P16:P22)*1)<2,"Need≥2",RSQ(IF(ISNUMBER(P16:P22),LN(P16:P22),FALSE),IF(ISNUMBER(P16:P22),LN(B6:B12),FALSE))),"N/A") | F40: =IFERROR(IF(SUMPRODUCT(ISNUMBER(P16:P22)*1)<3,"Need≥3",1-(1-(IFERROR(IF(SUMPRODUCT(ISNUMBER(P16:P22)*1)<2,"Need≥2",RSQ(IF(ISNUMBER(P16:P22),LN(P16:P22),FALSE),IF(ISNUMBER(P16:P22),LN(B6:B12),FALSE))),"N/A")))*(B40-1)/(B40-2)),"N/A") | G40: =IFERROR(IF(SUMPRODUCT(ISNUMBER(P16:P22)*1)<3,"Need≥3",SQRT((1-(IFERROR(IF(SUMPRODUCT(ISNUMBER(P16:P22)*1)<2,"Need≥2",RSQ(IF(ISNUMBER(P16:P22),LN(P16:P22),FALSE),IF(ISNUMBER(P16:P22),LN(B6:B12),FALSE))),"N/A")))*VAR(IF(ISNUMBER(P16:P22),LN(P16:P22),FALSE))/((B40-2)*VAR(IF(ISNUMBER(P16:P22),LN(B6:B12),FALSE))))),"N/A") | H40: =IFERROR(IF(SUMPRODUCT(ISNUMBER(BT16:BT22)*1)<2,"Need≥2",EXP(INTERCEPT(IF(ISNUMBER(BT16:BT22),LN(BT16:BT22),FALSE),IF(ISNUMBER(BT16:BT22),LN(BF6:BF12),FALSE)))),"N/A") | I40: =IFERROR(IF(SUMPRODUCT(ISNUMBER(BT16:BT22)*1)<2,"Need≥2",SLOPE(IF(ISNUMBER(BT16:BT22),LN(BT16:BT22),FALSE),IF(ISNUMBER(BT16:BT22),LN(BF6:BF12),FALSE))),"N/A") | J40: =IFERROR(IF(SUMPRODUCT(ISNUMBER(BT16:BT22)*1)<2,"Need≥2",RSQ(IF(ISNUMBER(BT16:BT22),LN(BT16:BT22),FALSE),IF(ISNUMBER(BT16:BT22),LN(BF6:BF12),FALSE))),"N/A") | K40: =IFERROR(IF(SUMPRODUCT(ISNUMBER(BT16:BT22)*1)<3,"Need≥3",1-(1-(IFERROR(IF(SUMPRODUCT(ISNUMBER(BT16:BT22)*1)<2,"Need≥2",RSQ(IF(ISNUMBER(BT16:BT22),LN(BT16:BT22),FALSE),IF(ISNUMBER(BT16:BT22),LN(BF6:BF12),FALSE))),"N/A")))*(B40-1)/(B40-2)),"N/A") | L40: =IFERROR(IF(SUMPRODUCT(ISNUMBER(BT16:BT22)*1)<3,"Need≥3",SQRT((1-(IFERROR(IF(SUMPRODUCT(ISNUMBER(BT16:BT22)*1)<2,"Need≥2",RSQ(IF(ISNUMBER(BT16:BT22),LN(BT16:BT22),FALSE),IF(ISNUMBER(BT16:BT22),LN(BF6:BF12),FALSE))),"N/A")))*VAR(IF(ISNUMBER(BT16:BT22),LN(BT16:BT22),FALSE))/((B40-2)*VAR(IF(ISNUMBER(BT16:BT22),LN(BF6:BF12),FALSE))))),"N/A") | M40: =IF(ISNUMBER(F40),IF(F40<0.85,"⚠ Check fit","OK"),"")
A41: Gd | B41: =SUMPRODUCT((ISNUMBER(Q16:Q22)*1)) | C41: =IFERROR(IF(SUMPRODUCT(ISNUMBER(Q16:Q22)*1)<2,"Need≥2",EXP(INTERCEPT(IF(ISNUMBER(Q16:Q22),LN(Q16:Q22),FALSE),IF(ISNUMBER(Q16:Q22),LN(B6:B12),FALSE)))),"N/A") | D41: =IFERROR(IF(SUMPRODUCT(ISNUMBER(Q16:Q22)*1)<2,"Need≥2",SLOPE(IF(ISNUMBER(Q16:Q22),LN(Q16:Q22),FALSE),IF(ISNUMBER(Q16:Q22),LN(B6:B12),FALSE))),"N/A") | E41: =IFERROR(IF(SUMPRODUCT(ISNUMBER(Q16:Q22)*1)<2,"Need≥2",RSQ(IF(ISNUMBER(Q16:Q22),LN(Q16:Q22),FALSE),IF(ISNUMBER(Q16:Q22),LN(B6:B12),FALSE))),"N/A") | F41: =IFERROR(IF(SUMPRODUCT(ISNUMBER(Q16:Q22)*1)<3,"Need≥3",1-(1-(IFERROR(IF(SUMPRODUCT(ISNUMBER(Q16:Q22)*1)<2,"Need≥2",RSQ(IF(ISNUMBER(Q16:Q22),LN(Q16:Q22),FALSE),IF(ISNUMBER(Q16:Q22),LN(B6:B12),FALSE))),"N/A")))*(B41-1)/(B41-2)),"N/A") | G41: =IFERROR(IF(SUMPRODUCT(ISNUMBER(Q16:Q22)*1)<3,"Need≥3",SQRT((1-(IFERROR(IF(SUMPRODUCT(ISNUMBER(Q16:Q22)*1)<2,"Need≥2",RSQ(IF(ISNUMBER(Q16:Q22),LN(Q16:Q22),FALSE),IF(ISNUMBER(Q16:Q22),LN(B6:B12),FALSE))),"N/A")))*VAR(IF(ISNUMBER(Q16:Q22),LN(Q16:Q22),FALSE))/((B41-2)*VAR(IF(ISNUMBER(Q16:Q22),LN(B6:B12),FALSE))))),"N/A") | H41: =IFERROR(IF(SUMPRODUCT(ISNUMBER(BU16:BU22)*1)<2,"Need≥2",EXP(INTERCEPT(IF(ISNUMBER(BU16:BU22),LN(BU16:BU22),FALSE),IF(ISNUMBER(BU16:BU22),LN(BF6:BF12),FALSE)))),"N/A") | I41: =IFERROR(IF(SUMPRODUCT(ISNUMBER(BU16:BU22)*1)<2,"Need≥2",SLOPE(IF(ISNUMBER(BU16:BU22),LN(BU16:BU22),FALSE),IF(ISNUMBER(BU16:BU22),LN(BF6:BF12),FALSE))),"N/A") | J41: =IFERROR(IF(SUMPRODUCT(ISNUMBER(BU16:BU22)*1)<2,"Need≥2",RSQ(IF(ISNUMBER(BU16:BU22),LN(BU16:BU22),FALSE),IF(ISNUMBER(BU16:BU22),LN(BF6:BF12),FALSE))),"N/A") | K41: =IFERROR(IF(SUMPRODUCT(ISNUMBER(BU16:BU22)*1)<3,"Need≥3",1-(1-(IFERROR(IF(SUMPRODUCT(ISNUMBER(BU16:BU22)*1)<2,"Need≥2",RSQ(IF(ISNUMBER(BU16:BU22),LN(BU16:BU22),FALSE),IF(ISNUMBER(BU16:BU22),LN(BF6:BF12),FALSE))),"N/A")))*(B41-1)/(B41-2)),"N/A") | L41: =IFERROR(IF(SUMPRODUCT(ISNUMBER(BU16:BU22)*1)<3,"Need≥3",SQRT((1-(IFERROR(IF(SUMPRODUCT(ISNUMBER(BU16:BU22)*1)<2,"Need≥2",RSQ(IF(ISNUMBER(BU16:BU22),LN(BU16:BU22),FALSE),IF(ISNUMBER(BU16:BU22),LN(BF6:BF12),FALSE))),"N/A")))*VAR(IF(ISNUMBER(BU16:BU22),LN(BU16:BU22),FALSE))/((B41-2)*VAR(IF(ISNUMBER(BU16:BU22),LN(BF6:BF12),FALSE))))),"N/A") | M41: =IF(ISNUMBER(F41),IF(F41<0.85,"⚠ Check fit","OK"),"")
A42: Tb | B42: =SUMPRODUCT((ISNUMBER(R16:R22)*1)) | C42: =IFERROR(IF(SUMPRODUCT(ISNUMBER(R16:R22)*1)<2,"Need≥2",EXP(INTERCEPT(IF(ISNUMBER(R16:R22),LN(R16:R22),FALSE),IF(ISNUMBER(R16:R22),LN(B6:B12),FALSE)))),"N/A") | D42: =IFERROR(IF(SUMPRODUCT(ISNUMBER(R16:R22)*1)<2,"Need≥2",SLOPE(IF(ISNUMBER(R16:R22),LN(R16:R22),FALSE),IF(ISNUMBER(R16:R22),LN(B6:B12),FALSE))),"N/A") | E42: =IFERROR(IF(SUMPRODUCT(ISNUMBER(R16:R22)*1)<2,"Need≥2",RSQ(IF(ISNUMBER(R16:R22),LN(R16:R22),FALSE),IF(ISNUMBER(R16:R22),LN(B6:B12),FALSE))),"N/A") | F42: =IFERROR(IF(SUMPRODUCT(ISNUMBER(R16:R22)*1)<3,"Need≥3",1-(1-(IFERROR(IF(SUMPRODUCT(ISNUMBER(R16:R22)*1)<2,"Need≥2",RSQ(IF(ISNUMBER(R16:R22),LN(R16:R22),FALSE),IF(ISNUMBER(R16:R22),LN(B6:B12),FALSE))),"N/A")))*(B42-1)/(B42-2)),"N/A") | G42: =IFERROR(IF(SUMPRODUCT(ISNUMBER(R16:R22)*1)<3,"Need≥3",SQRT((1-(IFERROR(IF(SUMPRODUCT(ISNUMBER(R16:R22)*1)<2,"Need≥2",RSQ(IF(ISNUMBER(R16:R22),LN(R16:R22),FALSE),IF(ISNUMBER(R16:R22),LN(B6:B12),FALSE))),"N/A")))*VAR(IF(ISNUMBER(R16:R22),LN(R16:R22),FALSE))/((B42-2)*VAR(IF(ISNUMBER(R16:R22),LN(B6:B12),FALSE))))),"N/A") | H42: =IFERROR(IF(SUMPRODUCT(ISNUMBER(BV16:BV22)*1)<2,"Need≥2",EXP(INTERCEPT(IF(ISNUMBER(BV16:BV22),LN(BV16:BV22),FALSE),IF(ISNUMBER(BV16:BV22),LN(BF6:BF12),FALSE)))),"N/A") | I42: =IFERROR(IF(SUMPRODUCT(ISNUMBER(BV16:BV22)*1)<2,"Need≥2",SLOPE(IF(ISNUMBER(BV16:BV22),LN(BV16:BV22),FALSE),IF(ISNUMBER(BV16:BV22),LN(BF6:BF12),FALSE))),"N/A") | J42: =IFERROR(IF(SUMPRODUCT(ISNUMBER(BV16:BV22)*1)<2,"Need≥2",RSQ(IF(ISNUMBER(BV16:BV22),LN(BV16:BV22),FALSE),IF(ISNUMBER(BV16:BV22),LN(BF6:BF12),FALSE))),"N/A") | K42: =IFERROR(IF(SUMPRODUCT(ISNUMBER(BV16:BV22)*1)<3,"Need≥3",1-(1-(IFERROR(IF(SUMPRODUCT(ISNUMBER(BV16:BV22)*1)<2,"Need≥2",RSQ(IF(ISNUMBER(BV16:BV22),LN(BV16:BV22),FALSE),IF(ISNUMBER(BV16:BV22),LN(BF6:BF12),FALSE))),"N/A")))*(B42-1)/(B42-2)),"N/A") | L42: =IFERROR(IF(SUMPRODUCT(ISNUMBER(BV16:BV22)*1)<3,"Need≥3",SQRT((1-(IFERROR(IF(SUMPRODUCT(ISNUMBER(BV16:BV22)*1)<2,"Need≥2",RSQ(IF(ISNUMBER(BV16:BV22),LN(BV16:BV22),FALSE),IF(ISNUMBER(BV16:BV22),LN(BF6:BF12),FALSE))),"N/A")))*VAR(IF(ISNUMBER(BV16:BV22),LN(BV16:BV22),FALSE))/((B42-2)*VAR(IF(ISNUMBER(BV16:BV22),LN(BF6:BF12),FALSE))))),"N/A") | M42: =IF(ISNUMBER(F42),IF(F42<0.85,"⚠ Check fit","OK"),"")
A43: Dy | B43: =SUMPRODUCT((ISNUMBER(S16:S22)*1)) | C43: =IFERROR(IF(SUMPRODUCT(ISNUMBER(S16:S22)*1)<2,"Need≥2",EXP(INTERCEPT(IF(ISNUMBER(S16:S22),LN(S16:S22),FALSE),IF(ISNUMBER(S16:S22),LN(B6:B12),FALSE)))),"N/A") | D43: =IFERROR(IF(SUMPRODUCT(ISNUMBER(S16:S22)*1)<2,"Need≥2",SLOPE(IF(ISNUMBER(S16:S22),LN(S16:S22),FALSE),IF(ISNUMBER(S16:S22),LN(B6:B12),FALSE))),"N/A") | E43: =IFERROR(IF(SUMPRODUCT(ISNUMBER(S16:S22)*1)<2,"Need≥2",RSQ(IF(ISNUMBER(S16:S22),LN(S16:S22),FALSE),IF(ISNUMBER(S16:S22),LN(B6:B12),FALSE))),"N/A") | F43: =IFERROR(IF(SUMPRODUCT(ISNUMBER(S16:S22)*1)<3,"Need≥3",1-(1-(IFERROR(IF(SUMPRODUCT(ISNUMBER(S16:S22)*1)<2,"Need≥2",RSQ(IF(ISNUMBER(S16:S22),LN(S16:S22),FALSE),IF(ISNUMBER(S16:S22),LN(B6:B12),FALSE))),"N/A")))*(B43-1)/(B43-2)),"N/A") | G43: =IFERROR(IF(SUMPRODUCT(ISNUMBER(S16:S22)*1)<3,"Need≥3",SQRT((1-(IFERROR(IF(SUMPRODUCT(ISNUMBER(S16:S22)*1)<2,"Need≥2",RSQ(IF(ISNUMBER(S16:S22),LN(S16:S22),FALSE),IF(ISNUMBER(S16:S22),LN(B6:B12),FALSE))),"N/A")))*VAR(IF(ISNUMBER(S16:S22),LN(S16:S22),FALSE))/((B43-2)*VAR(IF(ISNUMBER(S16:S22),LN(B6:B12),FALSE))))),"N/A") | H43: =IFERROR(IF(SUMPRODUCT(ISNUMBER(BW16:BW22)*1)<2,"Need≥2",EXP(INTERCEPT(IF(ISNUMBER(BW16:BW22),LN(BW16:BW22),FALSE),IF(ISNUMBER(BW16:BW22),LN(BF6:BF12),FALSE)))),"N/A") | I43: =IFERROR(IF(SUMPRODUCT(ISNUMBER(BW16:BW22)*1)<2,"Need≥2",SLOPE(IF(ISNUMBER(BW16:BW22),LN(BW16:BW22),FALSE),IF(ISNUMBER(BW16:BW22),LN(BF6:BF12),FALSE))),"N/A") | J43: =IFERROR(IF(SUMPRODUCT(ISNUMBER(BW16:BW22)*1)<2,"Need≥2",RSQ(IF(ISNUMBER(BW16:BW22),LN(BW16:BW22),FALSE),IF(ISNUMBER(BW16:BW22),LN(BF6:BF12),FALSE))),"N/A") | K43: =IFERROR(IF(SUMPRODUCT(ISNUMBER(BW16:BW22)*1)<3,"Need≥3",1-(1-(IFERROR(IF(SUMPRODUCT(ISNUMBER(BW16:BW22)*1)<2,"Need≥2",RSQ(IF(ISNUMBER(BW16:BW22),LN(BW16:BW22),FALSE),IF(ISNUMBER(BW16:BW22),LN(BF6:BF12),FALSE))),"N/A")))*(B43-1)/(B43-2)),"N/A") | L43: =IFERROR(IF(SUMPRODUCT(ISNUMBER(BW16:BW22)*1)<3,"Need≥3",SQRT((1-(IFERROR(IF(SUMPRODUCT(ISNUMBER(BW16:BW22)*1)<2,"Need≥2",RSQ(IF(ISNUMBER(BW16:BW22),LN(BW16:BW22),FALSE),IF(ISNUMBER(BW16:BW22),LN(BF6:BF12),FALSE))),"N/A")))*VAR(IF(ISNUMBER(BW16:BW22),LN(BW16:BW22),FALSE))/((B43-2)*VAR(IF(ISNUMBER(BW16:BW22),LN(BF6:BF12),FALSE))))),"N/A") | M43: =IF(ISNUMBER(F43),IF(F43<0.85,"⚠ Check fit","OK"),"")
...

Sheet SX Model
A1: STEADY-STATE SX SIMULATION — Primene JMT / H₂SO₄ Loading / HNO₃ Stripping — 26 Elements: Al Sc Fe Co Zn Ga Rb Y Zr La Ce Pr Nd Sm Eu Gd Tb Dy Ho Er Tm Yb Lu Hf Th U
A2: INPUT | D2: CALC | G2: STEP | J2: OUTPUT | M2: REF
A4: TDMA SOLVER — INPUT PANELS
A5: PANEL A — General Inputs | D5: PANEL B — Distribution Coefficients (live-linked from Regression) | J5: PANEL C — Feed Conc. (g/L) | N5: PANEL D — Results Summary | Q5: PANEL E — O/A Ratio Tracker
A6: n_ext (extraction stages) | B6: 3 | D6: Element | E6: P_load | F6: Q_load | G6: P_strip | H6: Q_strip | I6: Note | J6: Element | K6: X_feed (g/L) | L6: MW (g/mol) | N6: Metric | O6: Value (g/L) | Q6: Section | R6: O/A | S6: Note
A7: n_scr (scrub stages) | B7: 0 | D7: Al | E7: =IFERROR(IF(ISNUMBER(Regression!$C$26),Regression!$C$26,1.0),1.0) | F7: =IFERROR(IF(ISNUMBER(Regression!$D$26),Regression!$D$26,-1.0),-1.0) | G7: =IFERROR(IF(ISNUMBER(Regression!$H$26),Regression!$H$26,1.0),1.0) | H7: =IFERROR(IF(ISNUMBER(Regression!$I$26),Regression!$I$26,-1.2),-1.2) | I7: → regression | J7: Al | K7: 0.1 | L7: 26.98 | N7: Raffinate Al | O7: =HB91 | Q7: Extraction | R7: =$B$14/$B$12 | S7: O/F
A8: n_str (strip stages) | B8: 2 | D8: Sc | E8: =IFERROR(IF(ISNUMBER(Regression!$C$27),Regression!$C$27,1.0),1.0) | F8: =IFERROR(IF(ISNUMBER(Regression!$D$27),Regression!$D$27,-1.0),-1.0) | G8: =IFERROR(IF(ISNUMBER(Regression!$H$27),Regression!$H$27,1.0),1.0) | H8: =IFERROR(IF(ISNUMBER(Regression!$I$27),Regression!$I$27,-1.2),-1.2) | I8: → regression | J8: Sc | K8: 0.1 | L8: 44.96 | N8: Loaded Org Al | O8: =IFERROR(INDEX(I91:I115,$B$6),0) | Q8: Scrub | R8: =$B$14/MAX($B$13*$B$15,0.0001) | S8: O/(S·R)
A9: [H₂SO₄] Extraction (N) | B9: 0.5 | D9: Fe | E9: =IFERROR(IF(ISNUMBER(Regression!$C$28),Regression!$C$28,1.0),1.0) | F9: =IFERROR(IF(ISNUMBER(Regression!$D$28),Regression!$D$28,-1.0),-1.0) | G9: =IFERROR(IF(ISNUMBER(Regression!$H$28),Regression!$H$28,1.0),1.0) | H9: =IFERROR(IF(ISNUMBER(Regression!$I$28),Regression!$I$28,-1.2),-1.2) | I9: → regression | J9: Fe | K9: 0.1 | L9: 55.85 | N9: Pregnant Al | O9: =IFERROR(INDEX(HB91:HB115,$B$6+$B$7+$B$8),0) | Q9: Strip | R9: =$B$14/$B$13 | S9: O/S
A10: [H₂SO₄] Scrub (N) | B10: 1 | D10: Co | E10: =IFERROR(IF(ISNUMBER(Regression!$C$29),Regression!$C$29,1.0),1.0) | F10: =IFERROR(IF(ISNUMBER(Regression!$D$29),Regression!$D$29,-1.0),-1.0) | G10: =IFERROR(IF(ISNUMBER(Regression!$H$29),Regression!$H$29,1.0),1.0) | H10: =IFERROR(IF(ISNUMBER(Regression!$I$29),Regression!$I$29,-1.2),-1.2) | I10: → regression | J10: Co | K10: 0.1 | L10: 58.93 | N10: Raffinate Sc | O10: =HC91
A11: [HNO₃] Strip (N) | B11: 4 | D11: Zn | E11: =IFERROR(IF(ISNUMBER(Regression!$C$30),Regression!$C$30,1.0),1.0) | F11: =IFERROR(IF(ISNUMBER(Regression!$D$30),Regression!$D$30,-1.0),-1.0) | G11: =IFERROR(IF(ISNUMBER(Regression!$H$30),Regression!$H$30,1.0),1.0) | H11: =IFERROR(IF(ISNUMBER(Regression!$I$30),Regression!$I$30,-1.2),-1.2) | I11: → regression | J11: Zn | K11: 0.1 | L11: 65.38 | N11: Loaded Org Sc | O11: =IFERROR(INDEX(Q91:Q115,$B$6),0)
A12: F — Feed flow aq (L/min) | B12: 1 | D12: Ga | E12: =IFERROR(IF(ISNUMBER(Regression!$C$31),Regression!$C$31,1.0),1.0) | F12: =IFERROR(IF(ISNUMBER(Regression!$D$31),Regression!$D$31,-1.0),-1.0) | G12: =IFERROR(IF(ISNUMBER(Regression!$H$31),Regression!$H$31,1.0),1.0) | H12: =IFERROR(IF(ISNUMBER(Regression!$I$31),Regression!$I$31,-1.2),-1.2) | I12: → regression | J12: Ga | K12: 0.1 | L12: 69.72 | N12: Pregnant Sc | O12: =IFERROR(INDEX(HC91:HC115,$B$6+$B$7+$B$8),0)
A13: S — Strip flow aq (L/min) | B13: 1 | D13: Rb | E13: =IFERROR(IF(ISNUMBER(Regression!$C$32),Regression!$C$32,1.0),1.0) | F13: =IFERROR(IF(ISNUMBER(Regression!$D$32),Regression!$D$32,-1.0),-1.0) | G13: =IFERROR(IF(ISNUMBER(Regression!$H$32),Regression!$H$32,1.0),1.0) | H13: =IFERROR(IF(ISNUMBER(Regression!$I$32),Regression!$I$32,-1.2),-1.2) | I13: → regression | J13: Rb | K13: 0.1 | L13: 85.47 | N13: Raffinate Fe | O13: =HD91
A14: O — Org flow (L/min) | B14: 1 | D14: Y | E14: =IFERROR(IF(ISNUMBER(Regression!$C$33),Regression!$C$33,1.0),1.0) | F14: =IFERROR(IF(ISNUMBER(Regression!$D$33),Regression!$D$33,-1.0),-1.0) | G14: =IFERROR(IF(ISNUMBER(Regression!$H$33),Regression!$H$33,1.0),1.0) | H14: =IFERROR(IF(ISNUMBER(Regression!$I$33),Regression!$I$33,-1.2),-1.2) | I14: → regression | J14: Y | K14: 0.2 | L14: 88.91 | N14: Loaded Org Fe | O14: =IFERROR(INDEX(Y91:Y115,$B$6),0)
A15: R — Recycle ratio | B15: 0 | D15: Zr | E15: =IFERROR(IF(ISNUMBER(Regression!$C$34),Regression!$C$34,1.0),1.0) | F15: =IFERROR(IF(ISNUMBER(Regression!$D$34),Regression!$D$34,-1.0),-1.0) | G15: =IFERROR(IF(ISNUMBER(Regression!$H$34),Regression!$H$34,1.0),1.0) | H15: =IFERROR(IF(ISNUMBER(Regression!$I$34),Regression!$I$34,-1.2),-1.2) | I15: → regression | J15: Zr | K15: 1 | L15: 91.22 | N15: Pregnant Fe | O15: =IFERROR(INDEX(HD91:HD115,$B$6+$B$7+$B$8),0)
D16: La | E16: =IFERROR(IF(ISNUMBER(Regression!$C$35),Regression!$C$35,1.0),1.0) | F16: =IFERROR(IF(ISNUMBER(Regression!$D$35),Regression!$D$35,-1.0),-1.0) | G16: =IFERROR(IF(ISNUMBER(Regression!$H$35),Regression!$H$35,1.0),1.0) | H16: =IFERROR(IF(ISNUMBER(Regression!$I$35),Regression!$I$35,-1.2),-1.2) | I16: → regression | J16: La | K16: 0.5 | L16: 138.91 | N16: Raffinate Co | O16: =HE91
D17: Ce | E17: =IFERROR(IF(ISNUMBER(Regression!$C$36),Regression!$C$36,1.0),1.0) | F17: =IFERROR(IF(ISNUMBER(Regression!$D$36),Regression!$D$36,-1.0),-1.0) | G17: =IFERROR(IF(ISNUMBER(Regression!$H$36),Regression!$H$36,1.0),1.0) | H17: =IFERROR(IF(ISNUMBER(Regression!$I$36),Regression!$I$36,-1.2),-1.2) | I17: → regression | J17: Ce | K17: 0.5 | L17: 140.12 | N17: Loaded Org Co | O17: =IFERROR(INDEX(AG91:AG115,$B$6),0)
D18: Pr | E18: =IFERROR(IF(ISNUMBER(Regression!$C$37),Regression!$C$37,1.0),1.0) | F18: =IFERROR(IF(ISNUMBER(Regression!$D$37),Regression!$D$37,-1.0),-1.0) | G18: =IFERROR(IF(ISNUMBER(Regression!$H$37),Regression!$H$37,1.0),1.0) | H18: =IFERROR(IF(ISNUMBER(Regression!$I$37),Regression!$I$37,-1.2),-1.2) | I18: → regression | J18: Pr | K18: 0.1 | L18: 140.91 | N18: Pregnant Co | O18: =IFERROR(INDEX(HE91:HE115,$B$6+$B$7+$B$8),0)
D19: Nd | E19: =IFERROR(IF(ISNUMBER(Regression!$C$38),Regression!$C$38,1.0),1.0) | F19: =IFERROR(IF(ISNUMBER(Regression!$D$38),Regression!$D$38,-1.0),-1.0) | G19: =IFERROR(IF(ISNUMBER(Regression!$H$38),Regression!$H$38,1.0),1.0) | H19: =IFERROR(IF(ISNUMBER(Regression!$I$38),Regression!$I$38,-1.2),-1.2) | I19: → regression | J19: Nd | K19: 0.3 | L19: 144.24 | N19: Raffinate Zn | O19: =HF91
